Workbook

Sheet 초도
A1: 초도 기준 정리 / First-run planning
A2: 노란 칸만 입력하세요. 회색 칸은 자동 계산입니다. 입력한 내용은 내려받아 연 본인의 컴퓨터에만 저장됩니다. 작성 방법은 '사용법' 탭을 보세요. Yellow cells are inputs; grey cells are formulas. Nothing you type leaves your computer.
A3: 처음 만드는 물량(초도생산) 기준으로 만들고 파는 데 드는 총비용을 적고, 초도물량으로 본전이 되는지와 얼마나 빨리 팔아야 하는지를 4번 판정에서 봅니다. 규모를 키웠을 때는 '양산' 탭, 둘의 차이는 '비교' 탭에서 봅니다.
A5: 1. 가정 / Assumptions
A6: 업종 | E6: 제조 또는 서비스 (아래 수량·기간 항목의 이름이 바뀝니다)
A7: 판매 단위 (예: 낱개 1개, 6개입 세트, 1건) | E7: 판매가·수량·비용 모두 이 단위를 기준으로 적습니다. 한 번에 한 가지 판매 단위만 정리하세요
A8: =IF($B$6="서비스","목표 판매 수","초도생산 수량")&" (판매 단위 수"&IF($B$7<>""," · 1단위 = "&$B$7,"")&")" | E8: 제조: 초도생산 수량 (판매 단위 수). 서비스: 이 기간 안에 팔려는 목표 판매 수 — 수용 한도가 아니라 목표로 적으세요
A9: =IF($B$6="서비스","목표 판매 기간 (개월)","목표 소진기간 (개월)") | E9: 초도물량(서비스는 목표 판매 수)을 모두 판매하려는 기간
A10: 실제 판매가 (KRW) | E10: 고객이 실제로 내는 가격
A11: 부가세율 (%) | E11: 예: 10
A12: 위 판매가는 VAT 포함가인가? | E12: 예 / 아니오
A14: 2. 만드는 활동 / How to make — 런칭 직전까지
A15: 초도물량을 만드는 데 드는 일(to-do)을 한 줄씩 적고, 그 일에 드는 총비용을 적으세요. 제조: 재료·가공·금형·장치·포장 등 / 서비스: 기획·개발·디자인 인건비 등. 구분 없이 총액만 적습니다.
A16: 활동 (to-do) | B16: 총 비용 (KRW) | C16: 메모
A27: 만드는 총비용 합계 | B27: =SUM($B$17:$B$26)
A28: 3. 파는 활동 / How to sell — 런칭 전 준비와 판매 시 비용
A29: '런칭 전 총액'은 입점·샘플·초기 마케팅처럼 팔기 전에 쓰는 총비용입니다. '판매 시 …'는 팔 때마다 붙는 비용만 적습니다 (수수료·결제수수료·배송비·건당 광고비). 정액은 총액이 아니라 판매 단위 1개당 금액(판매 단위가 주문 1건이면 주문당 택배비도 여기), %는 퍼센트 숫자(예: 10)로 적으세요.
A30: 활동 (to-do) | B30: 금액 / 값 | C30: 구분 | D30: 메모
A41: 런칭 전 총액 합계 | B41: =SUMIF($C$31:$C$40,"런칭 전 총액",$B$31:$B$40)
A42: 판매 시 정액 (판매 단위당) 합계 | B42: =SUMIF($C$31:$C$40,"판매 시 정액 (판매 단위당)",$B$31:$B$40)
A43: 판매 시 순매출 대비 % 합계 | B43: =SUMIF($C$31:$C$40,"판매 시 순매출 대비 %",$B$31:$B$40)
A44: 판매 시 지불액 대비 % 합계 | B44: =SUMIF($C$31:$C$40,"판매 시 지불액 대비 %",$B$31:$B$40)
A45: 구분을 고르지 않은 행 수 | B45: =COUNTIFS($B$31:$B$40,"<>",$C$31:$C$40,"") | E45: 0이 아니면 구분을 선택하세요 (구분이 없는 행은 합계에 포함되지 않습니다)
A47: 3-2. 월 고정운영비 / Monthly fixed operating cost
A48: 물량과 무관하게 매달 나가는 비용 (임대료, 상시 인건비, 구독·툴 비용 등).
A49: 항목 | B49: 월 금액 (KRW) | C49: 메모
A56: 월 고정운영비 합계 | B56: =SUM($B$50:$B$55)
A58: 4. 판정 / Verdict — 초도물량으로 본전이 되는가
A59: 초도 기준 판단용 계산입니다 (재고·외상 시차와 추가 생산은 반영하지 않음). 정식 계산은 웹 계산기에서 하세요.
A60: 항목 | B60: 값 | E60: 설명
A61: 필수 입력 완료 | B61: =AND(ISNUMBER($B$10),ISNUMBER($B$11),OR($B$12="예",$B$12="아니오"),ISNUMBER($B$8),ISNUMBER($B$9)) | E61: 판매가·부가세율·VAT 여부·수량·소진기간이 모두 입력되면 TRUE
A62: 순매출 (VAT 제외 판매가) | B62: =IF(NOT($B$61),"",IF($B$12="예",$B$10/(1+$B$11/100),$B$10))
A63: 고객 지불액 (VAT 포함) | B63: =IF(NOT($B$61),"",IF($B$12="예",$B$10,$B$10*(1+$B$11/100)))
A64: 판매 단위당 변동비 (판매 시) | B64: =IF(NOT($B$61),"",$B$42+$B$43/100*$B$62+$B$44/100*$B$63) | E64: 정액 + 순매출 대비 % × 순매출 + 지불액 대비 % × 지불액
A65: 판매 단위당 남는 금액 | B65: =IF(NOT($B$61),"",$B$62-$B$64) | E65: 순매출 − 판매 단위당 변동비 (제작비·고정비 회수 전)
A66: 초도 총비용 | B66: =IF(NOT($B$61),"",$B$27+$B$41) | E66: 만드는 총비용 + 런칭 전 총액
A67: 회수해야 할 총액 | B67: =IF(NOT($B$61),"",$B$66+$B$56*$B$9) | E67: 초도 총비용 + 월 고정운영비 × 소진기간
A68: 본전에 필요한 누적 판매량 | B68: =IF(NOT($B$61),"",IF($B$65>0,$B$67/$B$65,"불가 (판매 단위당 남는 금액 ≤ 0)")) | E68: 회수해야 할 총액 ÷ 판매 단위당 남는 금액
A69: 필요 판매량 ÷ 수량 | B69: =IF(NOT($B$61),"",IF(AND(ISNUMBER($B$68),$B$8>0),$B$68/$B$8,"")) | E69: 100% 이하여야 초도물량으로 본전 가능
A70: 필요 월 판매량 (소진기간 내 본전) | B70: =IF(NOT($B$61),"",IF(AND(ISNUMBER($B$68),$B$9>0),$B$68/$B$9,"")) | E70: 누적 필요 판매량 ÷ 소진기간
...

Sheet 양산
A1: 양산 기준 정리 / Planning at scale
A2: 규모를 키워 다시 만들 때를 정리합니다. 이 탭의 값은 견적서나 근거 있는 가정으로 채우세요 (근거 없이 낙관적으로 쓰면 비교가 무의미합니다). 업종·부가세·VAT 포함 여부는 '초도' 탭 값을 그대로 씁니다.
A3: 판매가·변동비·월 고정운영비는 비워 두면 '초도' 탭 값을 그대로 씁니다. 바뀌는 항목만 입력하세요.
A5: 1. 양산 가정 / Assumptions at scale
A6: 양산 수량 (한 번에 만드는 수량, 판매 단위 수) | E6: 이 수량을 다시 만들 때의 반복 비용을 아래 2번에 적습니다
A7: 양산 시 월 목표 판매량 (판매 단위 수) | E7: 본전 판매가와 판정에 사용
A8: 양산 시 판매가 (KRW) | E8: 비우면 초도 판매가와 같음 (초도와 같은 VAT 기준)
A10: 2. 양산 시 만드는 비용 / Repeat production cost
A11: 같은 설비를 이미 갖고 있다고 보고, 양산 수량을 다시 만들 때 또 드는 비용(재료·가공·외주 제작·포장·건당 인건비)의 총비용을 적으세요. 초도 때 산 금형·장치는 여기에 다시 적지 않습니다.
A12: 활동 (to-do) | B12: 총 비용 (KRW, 양산 수량 기준) | C12: 메모
A21: 양산 시 만드는 총비용 합계 | B21: =SUM($B$13:$B$20)
A23: 3. 새로 드는 투자 / New investment
A24: 양산을 위해 새로 사는 설비나 증설 비용이 있으면 적으세요. 제품·서비스 수명주기(개월)로 나눠 월 고정비에 더합니다. 없으면 비워 두세요.
A25: 항목 | B25: 총 비용 (KRW) | C25: 메모
A30: 새 투자 합계 | B30: =SUM($B$26:$B$29)
A31: 제품/서비스 수명주기 (개월) | E31: 새 투자가 있으면 입력 (장치는 내용연수와 수명주기 중 짧은 쪽)
A33: 4. 판매·고정비 변경분 / Overrides (비우면 초도 값)
A34: 판매 시 정액 (판매 단위당 합계, KRW) | E34: 비우면 초도의 판매 시 정액 합계
A35: 판매 시 순매출 대비 % 합계 | E35: 비우면 초도 값
A36: 판매 시 지불액 대비 % 합계 | E36: 비우면 초도 값
A37: 월 고정운영비 (KRW) | E37: 비우면 초도의 월 고정운영비 합계
A39: 5. 판정 / Verdict at scale
A40: 양산 기준 판단용 계산입니다. 정식 계산은 웹 계산기에서 하세요.
A41: 항목 | B41: 값 | E41: 설명
A42: 적용 판매가 (KRW) | B42: =IF(ISNUMBER($B$8),$B$8,IF(ISNUMBER('초도'!$B$10),'초도'!$B$10,"")) | E42: 양산 판매가, 비었으면 초도 판매가
A43: 필수 입력 완료 | B43: =AND(ISNUMBER($B$42),ISNUMBER('초도'!$B$11),OR('초도'!$B$12="예",'초도'!$B$12="아니오"),ISNUMBER($B$6),ISNUMBER($B$7)) | E43: 적용 판매가·'초도' 탭의 부가세율·VAT 여부·양산 수량·월 목표 판매량이 입력되면 TRUE
A44: 순매출 (VAT 제외 판매가) | B44: =IF(NOT($B$43),"",IF('초도'!$B$12="예",$B$42/(1+'초도'!$B$11/100),$B$42))
A45: 고객 지불액 (VAT 포함) | B45: =IF(NOT($B$43),"",IF('초도'!$B$12="예",$B$42,$B$42*(1+'초도'!$B$11/100)))
A46: 판매 단위당 직접원가 (양산) | B46: =IF(NOT($B$43),"",IF($B$6>0,$B$21/$B$6,"수량 > 0 필요")) | E46: 양산 시 만드는 총비용 ÷ 양산 수량
A47: 적용 판매 시 정액 합계 | B47: =IF(NOT($B$43),"",IF(ISNUMBER($B$34),$B$34,'초도'!$B$42))
A48: 적용 순매출 대비 % 합계 | B48: =IF(NOT($B$43),"",IF(ISNUMBER($B$35),$B$35,'초도'!$B$43))
A49: 적용 지불액 대비 % 합계 | B49: =IF(NOT($B$43),"",IF(ISNUMBER($B$36),$B$36,'초도'!$B$44))
A50: 판매 단위당 변동비 (판매 시) | B50: =IF(NOT($B$43),"",$B$47+$B$48/100*$B$44+$B$49/100*$B$45)
A51: 판매 단위당 공헌이익 | B51: =IF(NOT($B$43),"",IF(ISNUMBER($B$46),$B$44-$B$46-$B$50,"")) | E51: 순매출 − 판매 단위당 직접원가 − 판매 단위당 변동비
A52: 적용 월 고정운영비 | B52: =IF(NOT($B$43),"",IF(ISNUMBER($B$37),$B$37,'초도'!$B$56))
A53: 월 상각액 (새 투자) | B53: =IF(NOT($B$43),"",IF($B$30=0,0,IF(N($B$31)>0,$B$30/$B$31,"수명주기 입력 필요"))) | E53: 새 투자 ÷ 수명주기
A54: 월 고정비 (상각 포함) | B54: =IF(NOT($B$43),"",IF(ISNUMBER($B$53),$B$52+$B$53,"")) | E54: → 계산기의 '월 고정운영비'에 입력
A55: 월 손익분기 판매량 | B55: =IF(NOT($B$43),"",IF(OR(NOT(ISNUMBER($B$54)),NOT(ISNUMBER($B$51))),"",IF($B$51>0,$B$54/$B$51,IF($B$54=0,"해당 없음","불가 (공헌이익 ≤ 0)")))) | E55: 월 고정비 ÷ 판매 단위당 공헌이익 (계산기 BEP와 같은 식)
A56: 월 손익분기 ÷ 월 목표 판매량 | B56: =IF(NOT($B$43),"",IF(AND(ISNUMBER($B$55),$B$7>0),$B$55/$B$7,"")) | E56: 100% 이하여야 목표 판매 속도로 본전
A57: 월 손익 (목표 월 판매량 기준) | B57: =IF(NOT($B$43),"",IF(AND(ISNUMBER($B$54),ISNUMBER($B$51)),$B$7*$B$51-$B$54,""))
...

Sheet 비교
A1: 초도 vs 양산 비교 / Comparison
A2: 두 탭의 값을 같은 정의로 나란히 보여줍니다. 양산 탭 값은 견적·가정이므로 '얼마나 개선되는가'의 방향을 보는 용도로 쓰세요.
A3: 월 손익분기는 계산기의 BEP와 같은 식(월 고정비 ÷ 판매 단위당 공헌이익)으로 양쪽을 맞췄습니다. 초도 쪽 직접원가는 초도 총비용으로 환산한 '초도 완전원가'입니다.
A5: 항목 | B5: 초도 | C5: 양산 | D5: 차이 (양산 − 초도) | E5: 설명
A6: 판매가 (KRW) | B6: ='초도'!$B$10 | C6: ='양산'!$B$42 | D6: =IF(AND(ISNUMBER(B6),ISNUMBER(C6)),C6-B6,"") | E6: 양산 탭의 적용 판매가
A7: 순매출 (VAT 제외) | B7: ='초도'!$B$62 | C7: ='양산'!$B$44 | D7: =IF(AND(ISNUMBER(B7),ISNUMBER(C7)),C7-B7,"")
A8: 판매 단위당 직접원가 | B8: ='초도'!$B$81 | C8: ='양산'!$B$46 | D8: =IF(AND(ISNUMBER(B8),ISNUMBER(C8)),C8-B8,"") | E8: 초도: 만드는 총비용 ÷ 초도수량 / 양산: 반복 비용 ÷ 양산 수량
A9: 판매 단위당 변동비 (판매 시) | B9: ='초도'!$B$64 | C9: ='양산'!$B$50 | D9: =IF(AND(ISNUMBER(B9),ISNUMBER(C9)),C9-B9,"")
A10: 판매 단위당 공헌이익 | B10: =IF(AND(ISNUMBER(B7),ISNUMBER(B8),ISNUMBER(B9)),B7-B8-B9,"") | C10: ='양산'!$B$51 | D10: =IF(AND(ISNUMBER(B10),ISNUMBER(C10)),C10-B10,"") | E10: 순매출 − 판매 단위당 직접원가 − 판매 단위당 변동비
A11: 월 고정비 (상각 포함) | B11: ='초도'!$B$85 | C11: ='양산'!$B$54 | D11: =IF(AND(ISNUMBER(B11),ISNUMBER(C11)),C11-B11,"") | E11: 초도: 월 고정운영비 + 런칭 전 총액 ÷ 소진기간 / 양산: 월 고정운영비 + 새 투자 상각
A12: 월 손익분기 판매량 | B12: =IF(AND(ISNUMBER(B11),ISNUMBER(B10)),IF(B10>0,B11/B10,IF(B11=0,"해당 없음","불가 (공헌이익 ≤ 0)")),"") | C12: ='양산'!$B$55 | D12: =IF(AND(ISNUMBER(B12),ISNUMBER(C12)),C12-B12,"") | E12: 월 고정비 ÷ 판매 단위당 공헌이익
A13: 본전 판매가 (VAT 기준은 초도 탭과 같음) | B13: ='초도'!$B$73 | C13: ='양산'!$B$58 | D13: =IF(AND(ISNUMBER(B13),ISNUMBER(C13)),C13-B13,"") | E13: 초도: 전량 판매·소진기간 기준 / 양산: 월 목표 판매량 기준 (기준 물량이 다릅니다)
A14: 판매 단위당 직접원가 절감률 | C14: =IF(AND(ISNUMBER(B8),ISNUMBER(C8),B8>0),1-C8/B8,"") | E14: 양산 시 판매 단위당 직접원가가 초도 대비 얼마나 줄었는지
A16: 해석 | B16: =IF(NOT(AND(ISNUMBER(B10),ISNUMBER(C10))),"두 탭의 필수 입력을 채우면 비교가 표시됩니다","양산하면 판매 단위당 직접원가가 "&TEXT(ABS(C14),"0%")&IF(C14>=0," 낮아지고"," 높아지고")&", 판매 단위당 공헌이익은 "&TEXT(B10,"#,##0")&"원에서 "&TEXT(C10,"#,##0")&"원이 됩니다. 월 손익분기는 "&IF(AND(ISNUMBER(B12),ISNUMBER(C12)),TEXT(B12,"#,##0.#")&"단위에서 "&TEXT(C12,"#,##0.#")&"단위로 바뀝니다.","확인이 필요합니다."))

Sheet 사용법
A1: 입력 정리 시트 사용법
A2: 이 시트는 웹 계산기에 넣을 값을 미리 정리하고, 처음 만드는 물량(초도)으로 본전이 되는지와 규모를 키웠을 때(양산)의 차이를 가늠해 보는 양식입니다. 입력한 내용은 이 파일(내 컴퓨터)에만 저장되며 어디로도 전송되지 않습니다. 노란 칸만 입력하고, 회색 칸은 자동 계산입니다.
A3: 탭 구성
A4: · 초도: 처음 만드는 물량 기준. 만드는 활동·파는 활동의 총비용을 적고 판정을 봅니다. · 양산: 규모를 키워 다시 만들 때 기준. 반복 비용, 새 투자, 바뀌는 변동비·고정비를 적습니다. · 비교: 초도와 양산을 같은 정의로 나란히 보여줍니다 (입력 없음). · 사용법: 지금 보는 탭입니다.
A5: 초도 탭 작성 순서
A6: ① 1. 가정: 업종, 판매 단위(낱개 1개, 6개입 세트, 1건처럼 한 번 팔 때의 단위. 판매가·수량·모든 비용이 이 단위 기준입니다), 초도생산 수량(판매 단위 수. 서비스는 수용 한도가 아니라 이 기간 안에 팔려는 목표 판매 수), 목표 소진기간(서비스는 목표 판매 기간, 개월), 판매가, 부가세, VAT 포함 여부를 입력합니다. ② 2. 만드는 활동: 런칭 직전까지 만드는 데 드는 일(to-do)을 한 줄씩 적고 그 일에 드는 총비용을 적습니다. 구분은 필요 없습니다. 제조는 재료·가공·금형·장치·포장, 서비스는 기획·개발·디자인 인건비 등입니다. ③ 3. 파는 활동: 런칭 전에 쓰는 총비용은 '런칭 전 총액'으로, 팔 때마다 붙는 비용은 '판매 시 …'로 구분을 고릅니다. 구분을 고르지 않은 행은 합계에서 빠지며, 표 아래 '구분을 고르지 않은 행 수'가 0이 아니면 선택하라는 뜻입니다. ④ 3-2. 월 고정운영비: 물량과 무관하게 매달 나가는 비용을 적습니다. ⑤ 4. 판정에서 본전 가능 여부를 읽고, 5. 계산기에 입력할 값을 웹 계산기에 옮겨 적습니다.
A7: 판매 단위
A8: 이 시트는 판매 품목 하나, 판매 단위 하나를 기준으로 정리합니다. 판매 단위가 낱개 1개이면 모든 금액이 낱개당, 6개입 세트이면 세트당, 주문 1건이면 주문당입니다. 단위가 다르면 환산해서 적으세요(낱개 원가 1,000원인 6개입 세트는 6,000원). 낱개와 묶음을 모두 판다면 주력 판매 단위로 한 번, 다른 단위로 한 번 따로 정리합니다.
A9: 판매 시 비용을 적는 법
A10: · 판매 시 정액(판매 단위당): 판매 단위 1개를 팔 때마다 붙는 고정 금액(배송비 등). 총액이 아니라 판매 단위 1개당 금액을 적습니다. 판매 단위가 주문 1건이면 주문당 택배비가 그대로 해당합니다. · 판매 시 순매출 대비 %: VAT를 뺀 판매가의 몇 %가 붙는 비용(플랫폼 수수료 등). 퍼센트 숫자만 적습니다(예: 10). · 판매 시 지불액 대비 %: VAT를 포함한 고객 결제액의 몇 %가 붙는 비용(결제수수료 등). 제작 관련 비용은 2번에, 판매·배송 비용은 3번에만 적으세요. 같은 비용을 두 곳에 넣으면 두 번 차감됩니다.
A11: 양산 탭 작성 순서
A12: ① 양산 수량(한 번에 만드는 수량)과 양산 시 월 목표 판매량을 입력합니다. ② 같은 설비를 이미 갖고 있다고 보고, 양산 수량을 다시 만들 때 또 드는 비용의 총비용을 적습니다. 초도 때 산 금형·장치는 다시 적지 않습니다. ③ 양산을 위해 새로 사는 설비가 있으면 적고, 수명주기(개월)를 입력합니다. ④ 판매가·변동비·월 고정운영비가 초도와 다르면 4번 칸에 적습니다. 비워 두면 초도 값을 그대로 씁니다. 이 탭의 값은 견적서나 근거 있는 가정으로 채우세요. 근거 없이 낙관적으로 쓰면 비교가 의미가 없습니다.
... A18: 초도 200개(판매 단위: 낱개 1개), 소진기간 6개월, 판매가 35,000원(VAT 포함 10%), 만드는 총비용 900만 원, 결제수수료 2.5%(판매 시 지불액 대비 %), 월 고정운영비 30만 원이면 → 회수해야 할 총액 1,080만 원, 판매 단위당 남는 금액 약 30,943원이라 본전에 약 349개가 필요합니다. 초도 200개를 모두 팔아도 본전이 안 된다는 판정이 나옵니다. 양산 탭에서 1,000개를 다시 만드는 반복 비용이 총 1,500만 원(판매 단위당 15,000원)이라면 판매 단위당 직접원가가 초도 45,000원에서 15,000원으로 줄어드는 것을 비교 탭에서 볼 수 있습니다.
