Workbook

Sheet 00_GUIDE
B2: MODE A + MODE B + MODE C + BEP + Scenario Compare + Volume Profit Excel Simulator — Pricing Harness
B4: Source of Truth 구조 (반드시 지켜야 하는 원칙)
B5: A. Formula Source of Truth = docs/features/mode_a_current_price/SPEC.md (MODE A), docs/features/mode_b_target_price/SPEC.md (MODE B), docs/features/mode_c_allowable_cost/SPEC.md (MODE C), docs/features/bep/SPEC.md (BEP) — 계산식의 공식 기준.
B6: B. Reference Implementation = core/engine/modes/mode_a.py, core/engine/modes/mode_b.py, core/engine/modes/mode_c.py, core/engine/modes/bep.py (Python), core/engine/economics.py(MODE A/BEP가 공유하는 Contribution Margin economic primitive — 실제 shared-cost 배부 엔진이 아님) — SPEC을 구현/테스트하는 기준 엔진. tests/test_mode_a.py 13/13, tests/test_mode_b.py 24/24, tests/test_mode_c.py 26/26, tests/test_bep.py 32/32 PASS.
B7: C. Interactive Simulation Layer = 이 Excel 파일 — 사용자가 값을 바꿔가며 결과 변화를 체감하는 도구. 수식은 반드시 A/B와 동일한 논리를 따른다. Excel은 독립적인 계산 엔진이 아니며, Python과 다른 계산 규칙을 만들지 않는다.
B8: D. Official Result Source = analysis_result.json (core/schemas/analysis_result.schema.json) — 실제 컨설팅 판단에 쓰는 공식 결과. Dashboard/Report/Quotation은 이 파일만 읽고, Excel 셀을 재계산하거나 직접 읽지 않는다.
B10: blank ≠ 0 원칙
B11: 필수 입력이 비어 있으면 그 값에 의존하는 결과는 0이 아니라 "미입력" 또는 "계산불가"로 표시됩니다. #DIV/0!, #VALUE!, #N/A 같은 Excel 기본 오류가 사용자 화면에 그대로 노출되지 않도록 모든 계산 셀은 IFERROR로 감쌌습니다.
B13: 이번 버전(v0.7)이 완전히 지원하는 범위
B14: • 01_SIMULATOR(MODE A)는 단일 컴포넌트 상품(simple one-time product, ecommerce product)만 대화형으로 지원합니다.
B15: • 03_PARITY_TEST(MODE A)에서 두 시나리오(simple / ecommerce) 모두 Python 엔진 결과와 대조 검증되어 있습니다.
B16: • 04_MODE_B_SIMULATOR는 단일 컴포넌트, shared-cost 없음 기준으로 목표가격(N/G/판매가/정가)을 대화형으로 계산합니다 — C/b/a는 이미 합산된 값을 입력합니다(01_SIMULATOR와 동일한 단순화).
... B29: 컴포넌트가 2개 이상인 하이브리드 상품은 단일-컴포넌트 Simulator 구조로 표현할 수 없어 이 Excel에서는 임의로 계산하지 않습니다. 아래는 Python Engine이 실제로 계산한 결과(core/schemas/examples/analysis_results/03_hybrid_hw_saas.analysis_result.json)를 그대로 옮긴 참고용 수치입니다 — 이 시트에서 재계산되지 않는 고정값입니다.
B30: Component | C30: Gross Profit | D30: Gross Profit Rate | E30: Contribution Margin
B31: hardware | C31: 181.48 USD (OK) | D31: 54.4% (OK) | E31: UNKNOWN — blended.allocation[pg_fee, channel_fee, maintenance_visit] 미구현
B32: saas_subscription | C32: 22.59 USD (OK) | D32: 87.1% (OK) | E32: UNKNOWN — blended.allocation[pg_fee, channel_fee, maintenance_visit] 미구현
B34: MODE B Shared Cost Status — Excel-only simulation control
B35: 04_MODE_B_SIMULATOR / 05_MODE_B_PARITY_TEST의 'Shared Cost Status' (none/unresolved/invalid) 입력은 client_input.schema.json의 정식 필드가 아닙니다. Shared Cost Status is an Excel simulation control only. It is not a field in client_input.schema.json. The production Python engine derives this state from actual cost item / applies_to_component / allocation_rule data (core/engine/modes/mode_b.py, dependency_rules.md §4) — never from a flag. 이 플래그는 shared 비용의 실제 배부(allocation) 금액을 계산하지 않고, 배부가 미구현/모순인 상태에서 MODE B가 UNKNOWN(unresolved) 또는 ERROR(invalid)를 정확히 산출하는지만 검증합니다 — Excel v0.2에도 실제 allocation engine은 추가되지 않았습니다. 아래는 05_MODE_B_PARITY_TEST의 #14/#15와 동일한 시나리오를 core/engine/modes/mode_b.py로 직접 실행한 결과(빌드 시점 고정값)입니다.
B36: Scenario | C36: denominator | D36: required_net_sales_ex_vat | E36: Warning code
B37: #14 shared + fixed_share (unresolved) | C37: UNKNOWN | D37: UNKNOWN | E37: UNSUPPORTED_SHARED_COST_ALLOCATION
B38: #15 shared + direct (invalid config) | C38: ERROR | D38: ERROR | E38: INVALID_ALLOCATION_CONFIGURATION
B39: MODE C Allocation Status — Excel-only simulation controls (TWO, independent)
B40: 06_MODE_C_SIMULATOR / 07_MODE_C_PARITY_TEST는 'Variable Cost Allocation Status'와 'Direct Cost Allocation Status', 2개의 독립된 Excel-only 컨트롤을 사용합니다 — 둘 다 client_input.schema.json의 정식 필드가 아닙니다(Excel simulation control only, not a field in client_input.schema.json). Variable Cost Allocation Status는 F/b/a(변동비)에 대한 공유비용 배부 상태를 시뮬레이션하며, unresolved/invalid일 때 allowable_direct_cost(ADC)·direct_cost_gap·expected_contribution_margin(_rate)까지 전부 UNKNOWN/ERROR로 전파됩니다. Direct Cost Allocation Status는 실제 직접원가(actual_direct_cost)에 대한 공유비용 배부 상태만 시뮬레이션하며, unresolved/invalid여도 이는 actual_direct_cost와 direct_cost_gap에만 영향을 주고 allowable_direct_cost·expected_contribution_margin(_rate)은 절대 영향받지 않습니다 — 이것이 MODE C Excel의 가장 중요한 dependency-isolation 테스트입니다 (docs/features/mode_c_allowable_cost/SPEC.md §9, core/schemas/dependency_rules.md §6). 07_MODE_C_PARITY_TEST의 TC19/TC20이 이 분리를 실시간으로 증명합니다.
B42: BEP — Break-Even Point
B43: • 질문: 현재 가격 + Contribution Margin + fixed operating cost → 손익분기 판매량(Q_BEP)은? BEP는 항상 현재 실제가격(actual_price, MODE A와 동일한 가격 기준) 기준으로 계산합니다 — MODE B의 required price나 MODE C의 market price를 대입하는 기능은 없습니다(향후 Scenario Compare 범위).
B44: • Fixed Operating Cost Basis(예: per_month)는 quantity unit이 아니라 analysis period context입니다. break_even_quantity_exact의 unit은 항상 "units"이고, Fixed Operating Cost가 정의된 기간을 별도의 'Analysis Period Basis' 셀로 분리해서 보여줍니다 — 둘을 하나로 섞어 표시하지 않습니다.
B45: • blank=UNKNOWN / 0=explicit zero 원칙은 BEP에도 동일하게 적용됩니다 — 단, fixed_operating_cost 항목이 '아예 없음'과 '항목은 있지만 값이 비어 있음'은 서로 다른 상태입니다(전자는 확정된 0/OK, 후자는 UNKNOWN) — Fixed Cost Allocation Status='none'으로 전자를, 'component'+금액 공백으로 후자를 표현합니다.
B46: • Contribution Margin per Unit(CMu)이 0 또는 음수인 경우는 계산 오류(ERROR)가 아니라 BEP 고유의 NOT_APPLICABLE 상태입니다 — 모든 입력값이 확정되어 있지만 손익분기 판매량이라는 개념 자체가 성립하지 않는 경우이며, 0이나 음수를 Q_BEP로 표시하지 않습니다. module status는 낮아지지 않습니다.
B47: • BEP v0.1은 단일 컴포넌트 상품만 지원합니다. 09_BEP_PARITY_TEST의 Component Count 컨트롤(Excel-only, schema field 아님)로 2개 이상 컴포넌트 시나리오를 시뮬레이션하면 즉시 ERROR/MULTI_COMPONENT_BEP_NOT_SUPPORTED로 처리되고, 이후 어떤 basis/CM/fixed-cost 계산도 수행되지 않습니다 — 이 gate가 다른 모든 validation보다 우선합니다.
B48: • 실제 shared-cost 배부(allocation) 엔진은 여전히 구현되어 있지 않습니다. Fixed Cost Allocation Status(component/unresolved/blended_only/invalid_direct)와 09_BEP_PARITY_TEST의 Fixed Cost Basis Consistency는 전부 Excel-only 시뮬레이션 컨트롤이며 client_input.schema.json의 정식 필드가 아닙니다. 특히 blended_only는 다른 모드의 '배부 대상 아님 → 0으로 제외' 규칙을 그대로 쓰지 않고 UNKNOWN으로 처리합니다 — BEP의 분자가 바로 fixed_operating_cost이기 때문에, 실제 존재하는 고정비를 조용히 0으로 만드는 것을 방지하기 위한 의도적인 편차입니다(docs/features/bep/SPEC.md §12).
B50: Scenario Compare — orchestration layer (not a new calculation mode)
B51: • Scenario Compare는 새로운 가격 계산 엔진이 아니라, 기존 MODE A/B/C/BEP를 여러 가정(base + override)에 대해 반복 실행하고 그 결과를 나란히 비교하는 orchestration layer입니다. Contribution Margin/BEP/VAT normalization/cost allocation 규칙을 새로 정의하지 않으며, 모든 숫자는 4개 모드의 기존 출력을 그대로 읽어온 것입니다.
B52: • Excel v0.1은 최대 5개 시나리오(A~E)로 제한됩니다 — 이는 presentation-layer 제한이며, Python Core(core/engine/scenario_compare.py)는 이 제한이 없습니다(2개 이상 임의 개수 지원).
... B58: • Scenario Compare는 자동 ranking이나 recommendation을 하지 않습니다 — 여러 시나리오를 나란히 비교해서 보여주는 descriptive comparison layer일 뿐입니다. '최적 시나리오' 자동 선정은 향후 AI Pricing Strategy layer의 몫입니다.

Sheet 01_SIMULATOR
B2: 01. MODE A Simulator — Interactive
B4: INPUT (노란 셀만 입력)
B5: Product Name | C5: 프리미엄 텀블러 | D5: 예시 시나리오 — 자유롭게 바꿔서 실험 가능
B6: Actual Price | C6: 35000 | D6: 실제 판매가격
B7: Price Includes VAT | C7: TRUE | D7: TRUE = 판매가에 VAT 포함 / FALSE = 별도 / 빈칸 = 모름
B8: VAT Rate | C8: 0.1 | D8: Price Includes VAT=FALSE면 비워둬도 계산 가능
B9: Product/Service Direct Cost | C9: 13500 | D9: Gross Profit 계산에 반영 (product_service_direct_cost)
B10: Channel Fee Rate | C10: 0 | D10: rate_of_net_sales — Net Sales(ex VAT)에 곱함. 채널 없으면 0
B11: PG Fee Rate | C11: 0.025 | D11: rate_of_gross_payment — Actual Price(결제금액)에 곱함
B12: Delivery / Installation Cost | C12: 3000 | D12: variable_selling_delivery (Harness 기본 분류)
B13: Other Variable Selling Cost | C13: 0 | D13: 기타 판매 변동비
B15: RESULT (계산값 — 직접 입력 금지)
B16: Actual Price ex VAT | C16: =IFERROR(IF(ISBLANK($C$6),"미입력",IF(ISBLANK($C$7),"미입력",IF($C$7=FALSE,$C$6,IF(ISBLANK($C$8),"미입력",$C$6/(1+$C$8))))),"계산불가") | D16: = actual_price / (1+vat_rate), 조건부 (SPEC.md §VAT 규칙) | J16: =IFERROR(IF(ISBLANK($C$6),"미입력",IF(ISBLANK($C$7),"미입력",IF($C$7=TRUE,$C$6,IF(ISBLANK($C$8),"미입력",$C$6*(1+$C$8))))),"계산불가")
B17: Direct Cost Total | C17: =IFERROR(IF(ISBLANK($C$9),"미입력",$C$9),"계산불가") | D17: product_service_direct_cost 합계
B18: Gross Profit | C18: =IFERROR(IF(AND(ISNUMBER($C$16),ISNUMBER($C$17)),$C$16-$C$17,"미입력"),"계산불가") | D18: = Actual Price ex VAT − Direct Cost Total
B19: Gross Profit Rate | C19: =IFERROR(IF(OR(NOT(ISNUMBER($C$18)),NOT(ISNUMBER($C$16))),"미입력",IF($C$16=0,"계산불가",$C$18/$C$16)),"계산불가") | D19: = Gross Profit / Actual Price ex VAT
B20: Variable Cost Total | C20: =IFERROR(IF(OR(ISBLANK($C$10),ISBLANK($C$11),ISBLANK($C$12),ISBLANK($C$13),NOT(ISNUMBER($C$16)),NOT(ISNUMBER($J$16))),"미입력",$C$16*$C$10+$J$16*$C$11+$C$12+$C$13),"계산불가") | D20: channel_fee×NetSales + pg_fee×GrossPayment(=NetSales×(1+VAT)) + delivery + other
B21: Contribution Margin | C21: =IFERROR(IF(AND(ISNUMBER($C$18),ISNUMBER($C$20)),$C$18-$C$20,"미입력"),"계산불가") | D21: = Gross Profit − Variable Cost Total (fixed cost 제외)
B22: Contribution Margin Rate | C22: =IFERROR(IF(OR(NOT(ISNUMBER($C$21)),NOT(ISNUMBER($C$16))),"미입력",IF($C$16=0,"계산불가",$C$21/$C$16)),"계산불가") | D22: = Contribution Margin / Actual Price ex VAT
B24: STATUS
B25: Data Complete / Incomplete / Error | C25: =IF((IF($C$16="계산불가",1,0)+IF($C$18="계산불가",1,0)+IF($C$19="계산불가",1,0)+IF($C$20="계산불가",1,0)+IF($C$21="계산불가",1,0)+IF($C$22="계산불가",1,0))>0,"Error",IF((IF(NOT(ISNUMBER($C$16)),1,0)+IF(NOT(ISNUMBER($C$18)),1,0)+IF(NOT(ISNUMBER($C$19)),1,0)+IF(NOT(ISNUMBER($C$20)),1,0)+IF(NOT(ISNUMBER($C$21)),1,0)+IF(NOT(ISNUMBER($C$22)),1,0))>0,"Incomplete","Complete"))
B26: Missing Inputs | C26: =IF($J$26="","없음",SUBSTITUTE(LEFT($J$26,LEN($J$26)-1),"|",", ")) | J26: =IF(ISBLANK($C$6),"판매가격|","")&IF(ISBLANK($C$7),"VAT포함여부|","")&IF(AND(NOT(ISBLANK($C$7)),ISBLANK($C$8),OR($C$7=TRUE,AND($C$7=FALSE,NOT(ISBLANK($C$11))))),"VAT율|","")&IF(ISBLANK($C$9),"직접원가|","")&IF(ISBLANK($C$10),"채널수수료율|","")&IF(ISBLANK($C$11),"PG수수료율|","")&IF(ISBLANK($C$12),"배송/설치비|","")&IF(ISBLANK($C$13),"기타변동비|","")
B27: Blocking Warning | C27: =IF(AND(ISNUMBER($C$18),ISNUMBER($C$21)),"없음 — 핵심 지표 계산 완료","Gross Profit: "&IF(ISNUMBER($C$18),"OK","UNKNOWN")&" | Contribution Margin: "&IF(ISNUMBER($C$21),"OK","UNKNOWN"))
B29: DASHBOARD CARD
B30: Current Price | E30: Net Sales | H30: Gross Profit
B31: =$C$6 | E31: =$C$16 | H31: =$C$18
B33: GP Rate | E33: Contribution Margin | H33: CM Rate
B34: =$C$19 | E34: =$C$21 | H34: =$C$22

Sheet 02_CALCULATION
B2: 02. Calculation Flow — 교육/QA용 (01_SIMULATOR 값을 그대로 참조)
B4: Step | C4: Live Value (from 01_SIMULATOR) | D4: Formula / Rule
B5: ① Actual Price | C5: ='01_SIMULATOR'!$C$6 | D5: 입력된 판매가격 그대로
B6: ↓
B7: ② VAT 처리 | C7: (VAT 포함여부에 따라 분기 — 결과는 다음 행 ③에 반영됨) | D7: price_includes_vat=FALSE → 그대로 사용 / TRUE → ÷(1+vat_rate)
B8: ↓
B9: ③ Net Sales (ex VAT) | C9: ='01_SIMULATOR'!$C$16 | D9: ①을 VAT 규칙대로 변환한 값
B10: ↓
B11: ④ Direct Cost | C11: ='01_SIMULATOR'!$C$9 | D11: product_service_direct_cost
B12: ↓
B13: ⑤ Gross Profit | C13: ='01_SIMULATOR'!$C$18 | D13: ③ − ④
B14: ↓
B15: ⑥ Variable Selling Cost | C15: ='01_SIMULATOR'!$C$20 | D15: channel/PG/배송/기타 변동비 합
B16: ↓
B17: ⑦ Contribution Margin | C17: ='01_SIMULATOR'!$C$21 | D17: ⑤ − ⑥ (고정비 제외)

Sheet 03_PARITY_TEST
B2: 03. Python Engine vs Excel Formula — Parity Test
B3: 각 케이스는 Excel에 동일 입력값을 리터럴로 심어 01_SIMULATOR와 같은 수식 패턴으로 독립 재계산하고, Python 참조값(core/engine/modes/mode_a.py 실행 결과, 빌드 시점에 고정)과 비교합니다. 허용오차 0.01(금액) / 0.0001(비율).
B5: Case 1 — Simple one-time product
B6: Metric | C6: Excel Result | D6: Python Reference | E6: Difference | F6: PASS / FAIL
B7: Actual Price ex VAT | C7: =I8 | D7: 31818.182 | E7: =IF(ISNUMBER(D7),IF(ISNUMBER(I8),ABS(I8-D7),"N/A"),"N/A") | F7: =IF(ISNUMBER(D7),IF(AND(ISNUMBER(I8),ABS(I8-D7)<=0.01),"PASS","FAIL"),IF(NOT(ISNUMBER(I8)),"PASS","FAIL")) | H7: (local inputs) | I7: 35000 | J7: TRUE | K7: 0.1 | L7: 13500 | M7: 0 | N7: 0.025 | O7: 3000 | P7: 0
B8: Direct Cost Total | C8: =J8 | D8: 13500 | E8: =IF(ISNUMBER(D8),IF(ISNUMBER(J8),ABS(J8-D8),"N/A"),"N/A") | F8: =IF(ISNUMBER(D8),IF(AND(ISNUMBER(J8),ABS(J8-D8)<=0.01),"PASS","FAIL"),IF(NOT(ISNUMBER(J8)),"PASS","FAIL")) | I8: =IFERROR(IF(ISBLANK($I$7),"미입력",IF(ISBLANK($J$7),"미입력",IF($J$7=FALSE,$I$7,IF(ISBLANK($K$7),"미입력",$I$7/(1+$K$7))))),"계산불가") | J8: =IFERROR(IF(ISBLANK($L$7),"미입력",$L$7),"계산불가") | K8: =IFERROR(IF(AND(ISNUMBER(I8),ISNUMBER(J8)),I8-J8,"미입력"),"계산불가") | L8: =IFERROR(IF(OR(NOT(ISNUMBER(K8)),NOT(ISNUMBER(I8))),"미입력",IF(I8=0,"계산불가",K8/I8)),"계산불가") | M8: =IFERROR(IF(OR(ISBLANK($M$7),ISBLANK($N$7),ISBLANK($O$7),ISBLANK($P$7),NOT(ISNUMBER(I8)),NOT(ISNUMBER(P8))),"미입력",I8*$M$7+P8*$N$7+$O$7+$P$7),"계산불가") | N8: =IFERROR(IF(AND(ISNUMBER(K8),ISNUMBER(M8)),K8-M8,"미입력"),"계산불가") | O8: =IFERROR(IF(OR(NOT(ISNUMBER(N8)),NOT(ISNUMBER(I8))),"미입력",IF(I8=0,"계산불가",N8/I8)),"계산불가") | P8: =IFERROR(IF(ISBLANK($I$7),"미입력",IF(ISBLANK($J$7),"미입력",IF($J$7=TRUE,$I$7,IF(ISBLANK($K$7),"미입력",$I$7*(1+$K$7))))),"계산불가")
B9: Gross Profit | C9: =K8 | D9: 18318.182 | E9: =IF(ISNUMBER(D9),IF(ISNUMBER(K8),ABS(K8-D9),"N/A"),"N/A") | F9: =IF(ISNUMBER(D9),IF(AND(ISNUMBER(K8),ABS(K8-D9)<=0.01),"PASS","FAIL"),IF(NOT(ISNUMBER(K8)),"PASS","FAIL"))
B10: Gross Profit Rate | C10: =L8 | D10: 0.57571429 | E10: =IF(ISNUMBER(D10),IF(ISNUMBER(L8),ABS(L8-D10),"N/A"),"N/A") | F10: =IF(ISNUMBER(D10),IF(AND(ISNUMBER(L8),ABS(L8-D10)<=0.0001),"PASS","FAIL"),IF(NOT(ISNUMBER(L8)),"PASS","FAIL"))
B11: Variable Cost Total | C11: =M8 | D11: 3875 | E11: =IF(ISNUMBER(D11),IF(ISNUMBER(M8),ABS(M8-D11),"N/A"),"N/A") | F11: =IF(ISNUMBER(D11),IF(AND(ISNUMBER(M8),ABS(M8-D11)<=0.01),"PASS","FAIL"),IF(NOT(ISNUMBER(M8)),"PASS","FAIL"))
B12: Contribution Margin | C12: =N8 | D12: 14443.182 | E12: =IF(ISNUMBER(D12),IF(ISNUMBER(N8),ABS(N8-D12),"N/A"),"N/A") | F12: =IF(ISNUMBER(D12),IF(AND(ISNUMBER(N8),ABS(N8-D12)<=0.01),"PASS","FAIL"),IF(NOT(ISNUMBER(N8)),"PASS","FAIL"))
B13: Contribution Margin Rate | C13: =O8 | D13: 0.45392857 | E13: =IF(ISNUMBER(D13),IF(ISNUMBER(O8),ABS(O8-D13),"N/A"),"N/A") | F13: =IF(ISNUMBER(D13),IF(AND(ISNUMBER(O8),ABS(O8-D13)<=0.0001),"PASS","FAIL"),IF(NOT(ISNUMBER(O8)),"PASS","FAIL"))
B15: Case 2 — VAT-inclusive, clean numbers
B16: Metric | C16: Excel Result | D16: Python Reference | E16: Difference | F16: PASS / FAIL
B17: Actual Price ex VAT | C17: =I18 | D17: 10000 | E17: =IF(ISNUMBER(D17),IF(ISNUMBER(I18),ABS(I18-D17),"N/A"),"N/A") | F17: =IF(ISNUMBER(D17),IF(AND(ISNUMBER(I18),ABS(I18-D17)<=0.01),"PASS","FAIL"),IF(NOT(ISNUMBER(I18)),"PASS","FAIL")) | H17: (local inputs) | I17: 11000 | J17: TRUE | K17: 0.1 | L17: 4000 | M17: 0 | N17: 0 | O17: 0 | P17: 0
B18: Direct Cost Total | C18: =J18 | D18: 4000 | E18: =IF(ISNUMBER(D18),IF(ISNUMBER(J18),ABS(J18-D18),"N/A"),"N/A") | F18: =IF(ISNUMBER(D18),IF(AND(ISNUMBER(J18),ABS(J18-D18)<=0.01),"PASS","FAIL"),IF(NOT(ISNUMBER(J18)),"PASS","FAIL")) | I18: =IFERROR(IF(ISBLANK($I$17),"미입력",IF(ISBLANK($J$17),"미입력",IF($J$17=FALSE,$I$17,IF(ISBLANK($K$17),"미입력",$I$17/(1+$K$17))))),"계산불가") | J18: =IFERROR(IF(ISBLANK($L$17),"미입력",$L$17),"계산불가") | K18: =IFERROR(IF(AND(ISNUMBER(I18),ISNUMBER(J18)),I18-J18,"미입력"),"계산불가") | L18: =IFERROR(IF(OR(NOT(ISNUMBER(K18)),NOT(ISNUMBER(I18))),"미입력",IF(I18=0,"계산불가",K18/I18)),"계산불가") | M18: =IFERROR(IF(OR(ISBLANK($M$17),ISBLANK($N$17),ISBLANK($O$17),ISBLANK($P$17),NOT(ISNUMBER(I18)),NOT(ISNUMBER(P18))),"미입력",I18*$M$17+P18*$N$17+$O$17+$P$17),"계산불가") | N18: =IFERROR(IF(AND(ISNUMBER(K18),ISNUMBER(M18)),K18-M18,"미입력"),"계산불가") | O18: =IFERROR(IF(OR(NOT(ISNUMBER(N18)),NOT(ISNUMBER(I18))),"미입력",IF(I18=0,"계산불가",N18/I18)),"계산불가") | P18: =IFERROR(IF(ISBLANK($I$17),"미입력",IF(ISBLANK($J$17),"미입력",IF($J$17=TRUE,$I$17,IF(ISBLANK($K$17),"미입력",$I$17*(1+$K$17))))),"계산불가")
B19: Gross Profit | C19: =K18 | D19: 6000 | E19: =IF(ISNUMBER(D19),IF(ISNUMBER(K18),ABS(K18-D19),"N/A"),"N/A") | F19: =IF(ISNUMBER(D19),IF(AND(ISNUMBER(K18),ABS(K18-D19)<=0.01),"PASS","FAIL"),IF(NOT(ISNUMBER(K18)),"PASS","FAIL"))
B20: Gross Profit Rate | C20: =L18 | D20: 0.6 | E20: =IF(ISNUMBER(D20),IF(ISNUMBER(L18),ABS(L18-D20),"N/A"),"N/A") | F20: =IF(ISNUMBER(D20),IF(AND(ISNUMBER(L18),ABS(L18-D20)<=0.0001),"PASS","FAIL"),IF(NOT(ISNUMBER(L18)),"PASS","FAIL"))
B21: Variable Cost Total | C21: =M18 | D21: 0 | E21: =IF(ISNUMBER(D21),IF(ISNUMBER(M18),ABS(M18-D21),"N/A"),"N/A") | F21: =IF(ISNUMBER(D21),IF(AND(ISNUMBER(M18),ABS(M18-D21)<=0.01),"PASS","FAIL"),IF(NOT(ISNUMBER(M18)),"PASS","FAIL"))
B22: Contribution Margin | C22: =N18 | D22: 6000 | E22: =IF(ISNUMBER(D22),IF(ISNUMBER(N18),ABS(N18-D22),"N/A"),"N/A") | F22: =IF(ISNUMBER(D22),IF(AND(ISNUMBER(N18),ABS(N18-D22)<=0.01),"PASS","FAIL"),IF(NOT(ISNUMBER(N18)),"PASS","FAIL"))
B23: Contribution Margin Rate | C23: =O18 | D23: 0.6 | E23: =IF(ISNUMBER(D23),IF(ISNUMBER(O18),ABS(O18-D23),"N/A"),"N/A") | F23: =IF(ISNUMBER(D23),IF(AND(ISNUMBER(O18),ABS(O18-D23)<=0.0001),"PASS","FAIL"),IF(NOT(ISNUMBER(O18)),"PASS","FAIL"))
B25: Case 3 — Ecommerce (channel fee + PG fee)
B26: Metric | C26: Excel Result | D26: Python Reference | E26: Difference | F26: PASS / FAIL
B27: Actual Price ex VAT | C27: =I28 | D27: 53636.364 | E27: =IF(ISNUMBER(D27),IF(ISNUMBER(I28),ABS(I28-D27),"N/A"),"N/A") | F27: =IF(ISNUMBER(D27),IF(AND(ISNUMBER(I28),ABS(I28-D27)<=0.01),"PASS","FAIL"),IF(NOT(ISNUMBER(I28)),"PASS","FAIL")) | H27: (local inputs) | I27: 59000 | J27: TRUE | K27: 0.1 | L27: 17000 | M27: 0.13 | N27: 0.028 | O27: 2500 | P27: 0
B28: Direct Cost Total | C28: =J28 | D28: 17000 | E28: =IF(ISNUMBER(D28),IF(ISNUMBER(J28),ABS(J28-D28),"N/A"),"N/A") | F28: =IF(ISNUMBER(D28),IF(AND(ISNUMBER(J28),ABS(J28-D28)<=0.01),"PASS","FAIL"),IF(NOT(ISNUMBER(J28)),"PASS","FAIL")) | I28: =IFERROR(IF(ISBLANK($I$27),"미입력",IF(ISBLANK($J$27),"미입력",IF($J$27=FALSE,$I$27,IF(ISBLANK($K$27),"미입력",$I$27/(1+$K$27))))),"계산불가") | J28: =IFERROR(IF(ISBLANK($L$27),"미입력",$L$27),"계산불가") | K28: =IFERROR(IF(AND(ISNUMBER(I28),ISNUMBER(J28)),I28-J28,"미입력"),"계산불가") | L28: =IFERROR(IF(OR(NOT(ISNUMBER(K28)),NOT(ISNUMBER(I28))),"미입력",IF(I28=0,"계산불가",K28/I28)),"계산불가") | M28: =IFERROR(IF(OR(ISBLANK($M$27),ISBLANK($N$27),ISBLANK($O$27),ISBLANK($P$27),NOT(ISNUMBER(I28)),NOT(ISNUMBER(P28))),"미입력",I28*$M$27+P28*$N$27+$O$27+$P$27),"계산불가") | N28: =IFERROR(IF(AND(ISNUMBER(K28),ISNUMBER(M28)),K28-M28,"미입력"),"계산불가") | O28: =IFERROR(IF(OR(NOT(ISNUMBER(N28)),NOT(ISNUMBER(I28))),"미입력",IF(I28=0,"계산불가",N28/I28)),"계산불가") | P28: =IFERROR(IF(ISBLANK($I$27),"미입력",IF(ISBLANK($J$27),"미입력",IF($J$27=TRUE,$I$27,IF(ISBLANK($K$27),"미입력",$I$27*(1+$K$27))))),"계산불가")
B29: Gross Profit | C29: =K28 | D29: 36636.364 | E29: =IF(ISNUMBER(D29),IF(ISNUMBER(K28),ABS(K28-D29),"N/A"),"N/A") | F29: =IF(ISNUMBER(D29),IF(AND(ISNUMBER(K28),ABS(K28-D29)<=0.01),"PASS","FAIL"),IF(NOT(ISNUMBER(K28)),"PASS","FAIL"))
B30: Gross Profit Rate | C30: =L28 | D30: 0.68305085 | E30: =IF(ISNUMBER(D30),IF(ISNUMBER(L28),ABS(L28-D30),"N/A"),"N/A") | F30: =IF(ISNUMBER(D30),IF(AND(ISNUMBER(L28),ABS(L28-D30)<=0.0001),"PASS","FAIL"),IF(NOT(ISNUMBER(L28)),"PASS","FAIL"))
B31: Variable Cost Total | C31: =M28 | D31: 11124.727 | E31: =IF(ISNUMBER(D31),IF(ISNUMBER(M28),ABS(M28-D31),"N/A"),"N/A") | F31: =IF(ISNUMBER(D31),IF(AND(ISNUMBER(M28),ABS(M28-D31)<=0.01),"PASS","FAIL"),IF(NOT(ISNUMBER(M28)),"PASS","FAIL"))
B32: Contribution Margin | C32: =N28 | D32: 25511.636 | E32: =IF(ISNUMBER(D32),IF(ISNUMBER(N28),ABS(N28-D32),"N/A"),"N/A") | F32: =IF(ISNUMBER(D32),IF(AND(ISNUMBER(N28),ABS(N28-D32)<=0.01),"PASS","FAIL"),IF(NOT(ISNUMBER(N28)),"PASS","FAIL"))
B33: Contribution Margin Rate | C33: =O28 | D33: 0.47564068 | E33: =IF(ISNUMBER(D33),IF(ISNUMBER(O28),ABS(O28-D33),"N/A"),"N/A") | F33: =IF(ISNUMBER(D33),IF(AND(ISNUMBER(O28),ABS(O28-D33)<=0.0001),"PASS","FAIL"),IF(NOT(ISNUMBER(O28)),"PASS","FAIL"))
B35: Case 4 — Incomplete input (UNKNOWN propagation)
B36: Metric | C36: Excel Result | D36: Python Reference | E36: Difference | F36: PASS / FAIL
B37: Actual Price ex VAT | C37: =I38 | D37: UNKNOWN | E37: =IF(ISNUMBER(D37),IF(ISNUMBER(I38),ABS(I38-D37),"N/A"),"N/A") | F37: =IF(ISNUMBER(D37),IF(AND(ISNUMBER(I38),ABS(I38-D37)<=0.01),"PASS","FAIL"),IF(NOT(ISNUMBER(I38)),"PASS","FAIL")) | H37: (local inputs) | I37: 35000
B38: Direct Cost Total | C38: =J38 | D38: UNKNOWN | E38: =IF(ISNUMBER(D38),IF(ISNUMBER(J38),ABS(J38-D38),"N/A"),"N/A") | F38: =IF(ISNUMBER(D38),IF(AND(ISNUMBER(J38),ABS(J38-D38)<=0.01),"PASS","FAIL"),IF(NOT(ISNUMBER(J38)),"PASS","FAIL")) | I38: =IFERROR(IF(ISBLANK($I$37),"미입력",IF(ISBLANK($J$37),"미입력",IF($J$37=FALSE,$I$37,IF(ISBLANK($K$37),"미입력",$I$37/(1+$K$37))))),"계산불가") | J38: =IFERROR(IF(ISBLANK($L$37),"미입력",$L$37),"계산불가") | K38: =IFERROR(IF(AND(ISNUMBER(I38),ISNUMBER(J38)),I38-J38,"미입력"),"계산불가") | L38: =IFERROR(IF(OR(NOT(ISNUMBER(K38)),NOT(ISNUMBER(I38))),"미입력",IF(I38=0,"계산불가",K38/I38)),"계산불가") | M38: =IFERROR(IF(OR(ISBLANK($M$37),ISBLANK($N$37),ISBLANK($O$37),ISBLANK($P$37),NOT(ISNUMBER(I38)),NOT(ISNUMBER(P38))),"미입력",I38*$M$37+P38*$N$37+$O$37+$P$37),"계산불가") | N38: =IFERROR(IF(AND(ISNUMBER(K38),ISNUMBER(M38)),K38-M38,"미입력"),"계산불가") | O38: =IFERROR(IF(OR(NOT(ISNUMBER(N38)),NOT(ISNUMBER(I38))),"미입력",IF(I38=0,"계산불가",N38/I38)),"계산불가") | P38: =IFERROR(IF(ISBLANK($I$37),"미입력",IF(ISBLANK($J$37),"미입력",IF($J$37=TRUE,$I$37,IF(ISBLANK($K$37),"미입력",$I$37*(1+$K$37))))),"계산불가")
B39: Gross Profit | C39: =K38 | D39: UNKNOWN | E39: =IF(ISNUMBER(D39),IF(ISNUMBER(K38),ABS(K38-D39),"N/A"),"N/A") | F39: =IF(ISNUMBER(D39),IF(AND(ISNUMBER(K38),ABS(K38-D39)<=0.01),"PASS","FAIL"),IF(NOT(ISNUMBER(K38)),"PASS","FAIL"))
B40: Gross Profit Rate | C40: =L38 | D40: UNKNOWN | E40: =IF(ISNUMBER(D40),IF(ISNUMBER(L38),ABS(L38-D40),"N/A"),"N/A") | F40: =IF(ISNUMBER(D40),IF(AND(ISNUMBER(L38),ABS(L38-D40)<=0.0001),"PASS","FAIL"),IF(NOT(ISNUMBER(L38)),"PASS","FAIL"))
B41: Variable Cost Total | C41: =M38 | D41: UNKNOWN | E41: =IF(ISNUMBER(D41),IF(ISNUMBER(M38),ABS(M38-D41),"N/A"),"N/A") | F41: =IF(ISNUMBER(D41),IF(AND(ISNUMBER(M38),ABS(M38-D41)<=0.01),"PASS","FAIL"),IF(NOT(ISNUMBER(M38)),"PASS","FAIL"))
B42: Contribution Margin | C42: =N38 | D42: UNKNOWN | E42: =IF(ISNUMBER(D42),IF(ISNUMBER(N38),ABS(N38-D42),"N/A"),"N/A") | F42: =IF(ISNUMBER(D42),IF(AND(ISNUMBER(N38),ABS(N38-D42)<=0.01),"PASS","FAIL"),IF(NOT(ISNUMBER(N38)),"PASS","FAIL"))
B43: Contribution Margin Rate | C43: =O38 | D43: UNKNOWN | E43: =IF(ISNUMBER(D43),IF(ISNUMBER(O38),ABS(O38-D43),"N/A"),"N/A") | F43: =IF(ISNUMBER(D43),IF(AND(ISNUMBER(O38),ABS(O38-D43)<=0.0001),"PASS","FAIL"),IF(NOT(ISNUMBER(O38)),"PASS","FAIL"))
B45: Case 5 — VAT-exclusive display + known VAT rate + gross-payment fee
B46: Metric | C46: Excel Result | D46: Python Reference | E46: Difference | F46: PASS / FAIL
...

Sheet 04_MODE_B_SIMULATOR
B2: 04. MODE B Simulator — Target Price (Interactive)
B4: INPUT (노란 셀만 입력, 단일 컴포넌트 / shared cost 없음 기준)
B5: Target Contribution Margin Rate (t) | C5: 0.3 | D5: 0 이상 1 미만이어야 함 (>=1 또는 <0은 ERROR)
B6: Fixed-Amount Direct + Variable Cost (C) | C6: 10000 | D6: 직접원가 + 금액형 변동비 합계 (rate 기반 항목 제외)
B7: Net-Sales Fee Rate (b) | C7: 0 | D7: rate_of_net_sales 합계 — Net Sales(N)에 곱함. 없으면 0
B8: Gross-Payment Fee Rate (a) | C8: 0.05 | D8: rate_of_gross_payment 합계 — Gross Payment(G)에 곱함. 없으면 0
B9: Price Includes VAT | C9: FALSE | D9: TRUE→표시가=G / FALSE→표시가=N / 빈칸=모름(UNKNOWN)
B10: VAT Rate (v) | C10: 0.1 | D10: a=0이면 N 계산에 불필요. G는 a와 무관하게 항상 필요 (SPEC.md §3)
B11: Discount Rate | D11: 0 이상 1 미만이어야 함. 빈칸=UNKNOWN → 정가 계산 불가
B12: Shared Cost Status (Excel simulation control — not a schema field) | C12: none | D12: Excel-only simulation control. NOT a field in client_input.schema.json — the production Python engine (core/engine/modes/mode_b.py) derives this state from actual cost item / applies_to_component / allocation_rule data, never from a flag like this. none=shared 비용 없음(정상 계산) / unresolved=by_component_revenue·fixed_share 등 배부 미구현(모든 결과 UNKNOWN) / invalid=shared+direct 모순 설정(모든 결과 ERROR). 실제 배부 엔진은 구현하지 않음 — 미지원 상태를 조용히 숫자로 만들지 않는지만 검증
B14: RESULT (계산값 — 직접 입력 금지)
B15: Denominator | C15: =IFERROR(IF($C$12="invalid","ERROR",IF($C$12="unresolved","UNKNOWN",IF(OR(AND(NOT(ISBLANK($C$5)),OR($C$5<0,$C$5>=1)),AND(NOT(ISBLANK($C$7)),$C$7<0),AND(NOT(ISBLANK($C$8)),$C$8<0),AND(NOT(ISBLANK($C$6)),$C$6<0)),"ERROR",IF(OR(ISBLANK($C$5),ISBLANK($C$7),ISBLANK($C$8)),"UNKNOWN",IF($C$8=0,IF(1-$C$5-$C$7<=0,"ERROR",1-$C$5-$C$7),IF(ISBLANK($C$10),"UNKNOWN",IF(1-$C$5-$C$7-$C$8*(1+$C$10)<=0,"ERROR",1-$C$5-$C$7-$C$8*(1+$C$10)))))))),"ERROR") | D15: D = 1 - t - b - a(1+v). D<=0 → ERROR (목표 불가능)
B16: Required Net Sales ex VAT | C16: =IFERROR(IF(ISBLANK($C$6),"UNKNOWN",IF(NOT(ISNUMBER(C15)),C15,$C$6/C15)),"ERROR") | D16: N = C / D
B17: Required Gross Payment incl VAT | C17: =IFERROR(IF(NOT(ISNUMBER(C16)),C16,IF(ISBLANK($C$10),"UNKNOWN",C16*(1+$C$10))),"ERROR") | D17: G = N × (1+v) — 항상 v 필요
B18: Required Selling Price | C18: =IFERROR(IF(ISBLANK($C$9),"UNKNOWN",IF($C$9=FALSE,C16,C17)),"ERROR") | D18: price_includes_vat=FALSE→N / TRUE→G / 빈칸→UNKNOWN
B19: Required List Price | C19: =IFERROR(IF(NOT(ISNUMBER(C18)),C18,IF(ISBLANK($C$11),"UNKNOWN",IF(OR($C$11<0,$C$11>=1),"ERROR",IF($C$11=0,C18,C18/(1-$C$11))))),"ERROR") | D19: = 판매가 / (1 - discount_rate)
B20: Expected Contribution Margin | C20: =IFERROR(IF(NOT(ISNUMBER(C16)),C16,IF($C$8=0,C16-$C$6-$C$7*C16,IF(NOT(ISNUMBER(C17)),C17,C16-$C$6-$C$7*C16-$C$8*C17))),"ERROR") | D20: = N - C - b×N - a×G (역산식과 독립적인 비용구조 재계산)
B21: Expected CM Rate | C21: =IFERROR(IF(NOT(ISNUMBER(C20)),C20,IF(C16=0,"ERROR",C20/C16)),"ERROR") | D21: = CM / N — 아래 Self-Check에서 목표 t와 별도 대조
B23: Self-Check: |CMR − t| ≤ 0.0001? | C23: =IF(NOT(ISNUMBER(C21)),"N/A",IF(ABS(C21-$C$5)<=0.0001,"PASS","FAIL")) | D23: 역산식(N=C/D)과 독립적으로 재계산한 CMR(=CM/N)이 목표 t와 tolerance 내에서 일치하는지 진단. MODE B의 공식 출력 metric은 아님 — 산술 오류를 잡기 위한 진단용.
B24: STATUS
B25: Overall Status | C25: =IF((IF(C15="ERROR",1,0)+IF(C16="ERROR",1,0)+IF(C17="ERROR",1,0)+IF(C18="ERROR",1,0)+IF(C19="ERROR",1,0)+IF(C20="ERROR",1,0)+IF(C21="ERROR",1,0))>0,"ERROR — 목표 불가능 또는 입력값 모순",IF((IF(C15="UNKNOWN",1,0)+IF(C16="UNKNOWN",1,0)+IF(C17="UNKNOWN",1,0)+IF(C18="UNKNOWN",1,0)+IF(C19="UNKNOWN",1,0)+IF(C20="UNKNOWN",1,0)+IF(C21="UNKNOWN",1,0))>0,"INCOMPLETE — 일부 지표 UNKNOWN","OK — 전체 계산 완료"))
B26: blank = UNKNOWN / 0 = explicit zero
B28: DASHBOARD CARD
B29: Required Net Sales ex VAT | E29: Required Gross Payment | H29: Required Selling Price
B30: =C16 | E30: =C17 | H30: =C18
B32: Required List Price | E32: Expected CM | H32: Expected CM Rate
B33: =C19 | E33: =C20 | H33: =C21

Sheet 05_MODE_B_PARITY_TEST
B2: 05. Python Engine vs Excel Formula — MODE B Parity Test
B3: 각 케이스는 Excel에 동일 입력값을 리터럴로 심어 04_MODE_B_SIMULATOR와 같은 수식(build_mode_b_formulas)으로 독립 재계산하고, Python 참조값(core/engine/modes/mode_b.py 실행 결과, 빌드 시점에 고정)과 비교합니다. 허용오차 0.01(금액) / 0.0001(비율). #14/#15는 shared-cost 시나리오로, 실제 배부(allocation) 금액을 계산하지는 않지만 Shared Cost Status 플래그를 통해 Excel이 '미지원 상태를 UNKNOWN/ERROR로 정확히 표시하는지'를 실시간으로 평가합니다 — 다른 13개 케이스와 동일하게 15/15 전부 live parity입니다.
B5: 1. Simple — no rate cost at all (TC1)
B6: Metric | C6: Excel Result | D6: Python Reference | E6: Difference | F6: PASS / FAIL
B7: Denominator | C7: =Q7 | D7: 0.6 | E7: =IF(ISNUMBER(D7),IF(ISNUMBER(Q7),ABS(Q7-D7),"N/A"),"N/A") | F7: =IF(ISNUMBER(D7),IF(AND(ISNUMBER(Q7),ABS(Q7-D7)<=0.01),"PASS","FAIL"),IF(AND(NOT(ISNUMBER(Q7)),Q7=D7),"PASS","FAIL")) | I7: 0.4 | J7: 10000 | K7: 0 | L7: 0 | M7: 0.1 | N7: FALSE | P7: none | Q7: =IFERROR(IF($P$7="invalid","ERROR",IF($P$7="unresolved","UNKNOWN",IF(OR(AND(NOT(ISBLANK($I$7)),OR($I$7<0,$I$7>=1)),AND(NOT(ISBLANK($K$7)),$K$7<0),AND(NOT(ISBLANK($L$7)),$L$7<0),AND(NOT(ISBLANK($J$7)),$J$7<0)),"ERROR",IF(OR(ISBLANK($I$7),ISBLANK($K$7),ISBLANK($L$7)),"UNKNOWN",IF($L$7=0,IF(1-$I$7-$K$7<=0,"ERROR",1-$I$7-$K$7),IF(ISBLANK($M$7),"UNKNOWN",IF(1-$I$7-$K$7-$L$7*(1+$M$7)<=0,"ERROR",1-$I$7-$K$7-$L$7*(1+$M$7)))))))),"ERROR") | R7: =IFERROR(IF(ISBLANK($J$7),"UNKNOWN",IF(NOT(ISNUMBER(Q7)),Q7,$J$7/Q7)),"ERROR") | S7: =IFERROR(IF(NOT(ISNUMBER(R7)),R7,IF(ISBLANK($M$7),"UNKNOWN",R7*(1+$M$7))),"ERROR") | T7: =IFERROR(IF(ISBLANK($N$7),"UNKNOWN",IF($N$7=FALSE,R7,S7)),"ERROR") | U7: =IFERROR(IF(NOT(ISNUMBER(T7)),T7,IF(ISBLANK($O$7),"UNKNOWN",IF(OR($O$7<0,$O$7>=1),"ERROR",IF($O$7=0,T7,T7/(1-$O$7))))),"ERROR") | V7: =IFERROR(IF(NOT(ISNUMBER(R7)),R7,IF($L$7=0,R7-$J$7-$K$7*R7,IF(NOT(ISNUMBER(S7)),S7,R7-$J$7-$K$7*R7-$L$7*S7))),"ERROR") | W7: =IFERROR(IF(NOT(ISNUMBER(V7)),V7,IF(R7=0,"ERROR",V7/R7)),"ERROR")
B8: Required Net Sales ex VAT | C8: =R7 | D8: 16666.667 | E8: =IF(ISNUMBER(D8),IF(ISNUMBER(R7),ABS(R7-D8),"N/A"),"N/A") | F8: =IF(ISNUMBER(D8),IF(AND(ISNUMBER(R7),ABS(R7-D8)<=0.01),"PASS","FAIL"),IF(AND(NOT(ISNUMBER(R7)),R7=D8),"PASS","FAIL"))
B9: Required Gross Payment incl VAT | C9: =S7 | D9: 18333.333 | E9: =IF(ISNUMBER(D9),IF(ISNUMBER(S7),ABS(S7-D9),"N/A"),"N/A") | F9: =IF(ISNUMBER(D9),IF(AND(ISNUMBER(S7),ABS(S7-D9)<=0.01),"PASS","FAIL"),IF(AND(NOT(ISNUMBER(S7)),S7=D9),"PASS","FAIL"))
B10: Required Selling Price | C10: =T7 | D10: 16666.667 | E10: =IF(ISNUMBER(D10),IF(ISNUMBER(T7),ABS(T7-D10),"N/A"),"N/A") | F10: =IF(ISNUMBER(D10),IF(AND(ISNUMBER(T7),ABS(T7-D10)<=0.01),"PASS","FAIL"),IF(AND(NOT(ISNUMBER(T7)),T7=D10),"PASS","FAIL"))
B11: Required List Price | C11: =U7 | D11: UNKNOWN | E11: =IF(ISNUMBER(D11),IF(ISNUMBER(U7),ABS(U7-D11),"N/A"),"N/A") | F11: =IF(ISNUMBER(D11),IF(AND(ISNUMBER(U7),ABS(U7-D11)<=0.01),"PASS","FAIL"),IF(AND(NOT(ISNUMBER(U7)),U7=D11),"PASS","FAIL"))
B12: Expected Contribution Margin | C12: =V7 | D12: 6666.6667 | E12: =IF(ISNUMBER(D12),IF(ISNUMBER(V7),ABS(V7-D12),"N/A"),"N/A") | F12: =IF(ISNUMBER(D12),IF(AND(ISNUMBER(V7),ABS(V7-D12)<=0.01),"PASS","FAIL"),IF(AND(NOT(ISNUMBER(V7)),V7=D12),"PASS","FAIL"))
B13: Expected CM Rate | C13: =W7 | D13: 0.4 | E13: =IF(ISNUMBER(D13),IF(ISNUMBER(W7),ABS(W7-D13),"N/A"),"N/A") | F13: =IF(ISNUMBER(D13),IF(AND(ISNUMBER(W7),ABS(W7-D13)<=0.0001),"PASS","FAIL"),IF(AND(NOT(ISNUMBER(W7)),W7=D13),"PASS","FAIL"))
B15: 2. Net-sales fee only (TC2)
B16: Metric | C16: Excel Result | D16: Python Reference | E16: Difference | F16: PASS / FAIL
B17: Denominator | C17: =Q17 | D17: 0.6 | E17: =IF(ISNUMBER(D17),IF(ISNUMBER(Q17),ABS(Q17-D17),"N/A"),"N/A") | F17: =IF(ISNUMBER(D17),IF(AND(ISNUMBER(Q17),ABS(Q17-D17)<=0.01),"PASS","FAIL"),IF(AND(NOT(ISNUMBER(Q17)),Q17=D17),"PASS","FAIL")) | I17: 0.3 | J17: 10000 | K17: 0.1 | L17: 0 | M17: 0.1 | N17: FALSE | P17: none | Q17: =IFERROR(IF($P$17="invalid","ERROR",IF($P$17="unresolved","UNKNOWN",IF(OR(AND(NOT(ISBLANK($I$17)),OR($I$17<0,$I$17>=1)),AND(NOT(ISBLANK($K$17)),$K$17<0),AND(NOT(ISBLANK($L$17)),$L$17<0),AND(NOT(ISBLANK($J$17)),$J$17<0)),"ERROR",IF(OR(ISBLANK($I$17),ISBLANK($K$17),ISBLANK($L$17)),"UNKNOWN",IF($L$17=0,IF(1-$I$17-$K$17<=0,"ERROR",1-$I$17-$K$17),IF(ISBLANK($M$17),"UNKNOWN",IF(1-$I$17-$K$17-$L$17*(1+$M$17)<=0,"ERROR",1-$I$17-$K$17-$L$17*(1+$M$17)))))))),"ERROR") | R17: =IFERROR(IF(ISBLANK($J$17),"UNKNOWN",IF(NOT(ISNUMBER(Q17)),Q17,$J$17/Q17)),"ERROR") | S17: =IFERROR(IF(NOT(ISNUMBER(R17)),R17,IF(ISBLANK($M$17),"UNKNOWN",R17*(1+$M$17))),"ERROR") | T17: =IFERROR(IF(ISBLANK($N$17),"UNKNOWN",IF($N$17=FALSE,R17,S17)),"ERROR") | U17: =IFERROR(IF(NOT(ISNUMBER(T17)),T17,IF(ISBLANK($O$17),"UNKNOWN",IF(OR($O$17<0,$O$17>=1),"ERROR",IF($O$17=0,T17,T17/(1-$O$17))))),"ERROR") | V17: =IFERROR(IF(NOT(ISNUMBER(R17)),R17,IF($L$17=0,R17-$J$17-$K$17*R17,IF(NOT(ISNUMBER(S17)),S17,R17-$J$17-$K$17*R17-$L$17*S17))),"ERROR") | W17: =IFERROR(IF(NOT(ISNUMBER(V17)),V17,IF(R17=0,"ERROR",V17/R17)),"ERROR")
B18: Required Net Sales ex VAT | C18: =R17 | D18: 16666.667 | E18: =IF(ISNUMBER(D18),IF(ISNUMBER(R17),ABS(R17-D18),"N/A"),"N/A") | F18: =IF(ISNUMBER(D18),IF(AND(ISNUMBER(R17),ABS(R17-D18)<=0.01),"PASS","FAIL"),IF(AND(NOT(ISNUMBER(R17)),R17=D18),"PASS","FAIL"))
B19: Required Gross Payment incl VAT | C19: =S17 | D19: 18333.333 | E19: =IF(ISNUMBER(D19),IF(ISNUMBER(S17),ABS(S17-D19),"N/A"),"N/A") | F19: =IF(ISNUMBER(D19),IF(AND(ISNUMBER(S17),ABS(S17-D19)<=0.01),"PASS","FAIL"),IF(AND(NOT(ISNUMBER(S17)),S17=D19),"PASS","FAIL"))
B20: Required Selling Price | C20: =T17 | D20: 16666.667 | E20: =IF(ISNUMBER(D20),IF(ISNUMBER(T17),ABS(T17-D20),"N/A"),"N/A") | F20: =IF(ISNUMBER(D20),IF(AND(ISNUMBER(T17),ABS(T17-D20)<=0.01),"PASS","FAIL"),IF(AND(NOT(ISNUMBER(T17)),T17=D20),"PASS","FAIL"))
B21: Required List Price | C21: =U17 | D21: UNKNOWN | E21: =IF(ISNUMBER(D21),IF(ISNUMBER(U17),ABS(U17-D21),"N/A"),"N/A") | F21: =IF(ISNUMBER(D21),IF(AND(ISNUMBER(U17),ABS(U17-D21)<=0.01),"PASS","FAIL"),IF(AND(NOT(ISNUMBER(U17)),U17=D21),"PASS","FAIL"))
B22: Expected Contribution Margin | C22: =V17 | D22: 5000 | E22: =IF(ISNUMBER(D22),IF(ISNUMBER(V17),ABS(V17-D22),"N/A"),"N/A") | F22: =IF(ISNUMBER(D22),IF(AND(ISNUMBER(V17),ABS(V17-D22)<=0.01),"PASS","FAIL"),IF(AND(NOT(ISNUMBER(V17)),V17=D22),"PASS","FAIL"))
B23: Expected CM Rate | C23: =W17 | D23: 0.3 | E23: =IF(ISNUMBER(D23),IF(ISNUMBER(W17),ABS(W17-D23),"N/A"),"N/A") | F23: =IF(ISNUMBER(D23),IF(AND(ISNUMBER(W17),ABS(W17-D23)<=0.0001),"PASS","FAIL"),IF(AND(NOT(ISNUMBER(W17)),W17=D23),"PASS","FAIL"))
B25: 3. Gross-payment fee only, VAT-exclusive display (TC3)
B26: Metric | C26: Excel Result | D26: Python Reference | E26: Difference | F26: PASS / FAIL
B27: Denominator | C27: =Q27 | D27: 0.645 | E27: =IF(ISNUMBER(D27),IF(ISNUMBER(Q27),ABS(Q27-D27),"N/A"),"N/A") | F27: =IF(ISNUMBER(D27),IF(AND(ISNUMBER(Q27),ABS(Q27-D27)<=0.01),"PASS","FAIL"),IF(AND(NOT(ISNUMBER(Q27)),Q27=D27),"PASS","FAIL")) | I27: 0.3 | J27: 10000 | K27: 0 | L27: 0.05 | M27: 0.1 | N27: FALSE | P27: none | Q27: =IFERROR(IF($P$27="invalid","ERROR",IF($P$27="unresolved","UNKNOWN",IF(OR(AND(NOT(ISBLANK($I$27)),OR($I$27<0,$I$27>=1)),AND(NOT(ISBLANK($K$27)),$K$27<0),AND(NOT(ISBLANK($L$27)),$L$27<0),AND(NOT(ISBLANK($J$27)),$J$27<0)),"ERROR",IF(OR(ISBLANK($I$27),ISBLANK($K$27),ISBLANK($L$27)),"UNKNOWN",IF($L$27=0,IF(1-$I$27-$K$27<=0,"ERROR",1-$I$27-$K$27),IF(ISBLANK($M$27),"UNKNOWN",IF(1-$I$27-$K$27-$L$27*(1+$M$27)<=0,"ERROR",1-$I$27-$K$27-$L$27*(1+$M$27)))))))),"ERROR") | R27: =IFERROR(IF(ISBLANK($J$27),"UNKNOWN",IF(NOT(ISNUMBER(Q27)),Q27,$J$27/Q27)),"ERROR") | S27: =IFERROR(IF(NOT(ISNUMBER(R27)),R27,IF(ISBLANK($M$27),"UNKNOWN",R27*(1+$M$27))),"ERROR") | T27: =IFERROR(IF(ISBLANK($N$27),"UNKNOWN",IF($N$27=FALSE,R27,S27)),"ERROR") | U27: =IFERROR(IF(NOT(ISNUMBER(T27)),T27,IF(ISBLANK($O$27),"UNKNOWN",IF(OR($O$27<0,$O$27>=1),"ERROR",IF($O$27=0,T27,T27/(1-$O$27))))),"ERROR") | V27: =IFERROR(IF(NOT(ISNUMBER(R27)),R27,IF($L$27=0,R27-$J$27-$K$27*R27,IF(NOT(ISNUMBER(S27)),S27,R27-$J$27-$K$27*R27-$L$27*S27))),"ERROR") | W27: =IFERROR(IF(NOT(ISNUMBER(V27)),V27,IF(R27=0,"ERROR",V27/R27)),"ERROR")
B28: Required Net Sales ex VAT | C28: =R27 | D28: 15503.876 | E28: =IF(ISNUMBER(D28),IF(ISNUMBER(R27),ABS(R27-D28),"N/A"),"N/A") | F28: =IF(ISNUMBER(D28),IF(AND(ISNUMBER(R27),ABS(R27-D28)<=0.01),"PASS","FAIL"),IF(AND(NOT(ISNUMBER(R27)),R27=D28),"PASS","FAIL"))
B29: Required Gross Payment incl VAT | C29: =S27 | D29: 17054.264 | E29: =IF(ISNUMBER(D29),IF(ISNUMBER(S27),ABS(S27-D29),"N/A"),"N/A") | F29: =IF(ISNUMBER(D29),IF(AND(ISNUMBER(S27),ABS(S27-D29)<=0.01),"PASS","FAIL"),IF(AND(NOT(ISNUMBER(S27)),S27=D29),"PASS","FAIL"))
B30: Required Selling Price | C30: =T27 | D30: 15503.876 | E30: =IF(ISNUMBER(D30),IF(ISNUMBER(T27),ABS(T27-D30),"N/A"),"N/A") | F30: =IF(ISNUMBER(D30),IF(AND(ISNUMBER(T27),ABS(T27-D30)<=0.01),"PASS","FAIL"),IF(AND(NOT(ISNUMBER(T27)),T27=D30),"PASS","FAIL"))
B31: Required List Price | C31: =U27 | D31: UNKNOWN | E31: =IF(ISNUMBER(D31),IF(ISNUMBER(U27),ABS(U27-D31),"N/A"),"N/A") | F31: =IF(ISNUMBER(D31),IF(AND(ISNUMBER(U27),ABS(U27-D31)<=0.01),"PASS","FAIL"),IF(AND(NOT(ISNUMBER(U27)),U27=D31),"PASS","FAIL"))
B32: Expected Contribution Margin | C32: =V27 | D32: 4651.1628 | E32: =IF(ISNUMBER(D32),IF(ISNUMBER(V27),ABS(V27-D32),"N/A"),"N/A") | F32: =IF(ISNUMBER(D32),IF(AND(ISNUMBER(V27),ABS(V27-D32)<=0.01),"PASS","FAIL"),IF(AND(NOT(ISNUMBER(V27)),V27=D32),"PASS","FAIL"))
B33: Expected CM Rate | C33: =W27 | D33: 0.3 | E33: =IF(ISNUMBER(D33),IF(ISNUMBER(W27),ABS(W27-D33),"N/A"),"N/A") | F33: =IF(ISNUMBER(D33),IF(AND(ISNUMBER(W27),ABS(W27-D33)<=0.0001),"PASS","FAIL"),IF(AND(NOT(ISNUMBER(W27)),W27=D33),"PASS","FAIL"))
B35: 4. VAT-inclusive display, both fee types (TC4)
B36: Metric | C36: Excel Result | D36: Python Reference | E36: Difference | F36: PASS / FAIL
B37: Denominator | C37: =Q37 | D37: 0.567 | E37: =IF(ISNUMBER(D37),IF(ISNUMBER(Q37),ABS(Q37-D37),"N/A"),"N/A") | F37: =IF(ISNUMBER(D37),IF(AND(ISNUMBER(Q37),ABS(Q37-D37)<=0.01),"PASS","FAIL"),IF(AND(NOT(ISNUMBER(Q37)),Q37=D37),"PASS","FAIL")) | I37: 0.3 | J37: 10000 | K37: 0.1 | L37: 0.03 | M37: 0.1 | N37: TRUE | P37: none | Q37: =IFERROR(IF($P$37="invalid","ERROR",IF($P$37="unresolved","UNKNOWN",IF(OR(AND(NOT(ISBLANK($I$37)),OR($I$37<0,$I$37>=1)),AND(NOT(ISBLANK($K$37)),$K$37<0),AND(NOT(ISBLANK($L$37)),$L$37<0),AND(NOT(ISBLANK($J$37)),$J$37<0)),"ERROR",IF(OR(ISBLANK($I$37),ISBLANK($K$37),ISBLANK($L$37)),"UNKNOWN",IF($L$37=0,IF(1-$I$37-$K$37<=0,"ERROR",1-$I$37-$K$37),IF(ISBLANK($M$37),"UNKNOWN",IF(1-$I$37-$K$37-$L$37*(1+$M$37)<=0,"ERROR",1-$I$37-$K$37-$L$37*(1+$M$37)))))))),"ERROR") | R37: =IFERROR(IF(ISBLANK($J$37),"UNKNOWN",IF(NOT(ISNUMBER(Q37)),Q37,$J$37/Q37)),"ERROR") | S37: =IFERROR(IF(NOT(ISNUMBER(R37)),R37,IF(ISBLANK($M$37),"UNKNOWN",R37*(1+$M$37))),"ERROR") | T37: =IFERROR(IF(ISBLANK($N$37),"UNKNOWN",IF($N$37=FALSE,R37,S37)),"ERROR") | U37: =IFERROR(IF(NOT(ISNUMBER(T37)),T37,IF(ISBLANK($O$37),"UNKNOWN",IF(OR($O$37<0,$O$37>=1),"ERROR",IF($O$37=0,T37,T37/(1-$O$37))))),"ERROR") | V37: =IFERROR(IF(NOT(ISNUMBER(R37)),R37,IF($L$37=0,R37-$J$37-$K$37*R37,IF(NOT(ISNUMBER(S37)),S37,R37-$J$37-$K$37*R37-$L$37*S37))),"ERROR") | W37: =IFERROR(IF(NOT(ISNUMBER(V37)),V37,IF(R37=0,"ERROR",V37/R37)),"ERROR")
B38: Required Net Sales ex VAT | C38: =R37 | D38: 17636.684 | E38: =IF(ISNUMBER(D38),IF(ISNUMBER(R37),ABS(R37-D38),"N/A"),"N/A") | F38: =IF(ISNUMBER(D38),IF(AND(ISNUMBER(R37),ABS(R37-D38)<=0.01),"PASS","FAIL"),IF(AND(NOT(ISNUMBER(R37)),R37=D38),"PASS","FAIL"))
B39: Required Gross Payment incl VAT | C39: =S37 | D39: 19400.353 | E39: =IF(ISNUMBER(D39),IF(ISNUMBER(S37),ABS(S37-D39),"N/A"),"N/A") | F39: =IF(ISNUMBER(D39),IF(AND(ISNUMBER(S37),ABS(S37-D39)<=0.01),"PASS","FAIL"),IF(AND(NOT(ISNUMBER(S37)),S37=D39),"PASS","FAIL"))
B40: Required Selling Price | C40: =T37 | D40: 19400.353 | E40: =IF(ISNUMBER(D40),IF(ISNUMBER(T37),ABS(T37-D40),"N/A"),"N/A") | F40: =IF(ISNUMBER(D40),IF(AND(ISNUMBER(T37),ABS(T37-D40)<=0.01),"PASS","FAIL"),IF(AND(NOT(ISNUMBER(T37)),T37=D40),"PASS","FAIL"))
B41: Required List Price | C41: =U37 | D41: UNKNOWN | E41: =IF(ISNUMBER(D41),IF(ISNUMBER(U37),ABS(U37-D41),"N/A"),"N/A") | F41: =IF(ISNUMBER(D41),IF(AND(ISNUMBER(U37),ABS(U37-D41)<=0.01),"PASS","FAIL"),IF(AND(NOT(ISNUMBER(U37)),U37=D41),"PASS","FAIL"))
B42: Expected Contribution Margin | C42: =V37 | D42: 5291.0053 | E42: =IF(ISNUMBER(D42),IF(ISNUMBER(V37),ABS(V37-D42),"N/A"),"N/A") | F42: =IF(ISNUMBER(D42),IF(AND(ISNUMBER(V37),ABS(V37-D42)<=0.01),"PASS","FAIL"),IF(AND(NOT(ISNUMBER(V37)),V37=D42),"PASS","FAIL"))
B43: Expected CM Rate | C43: =W37 | D43: 0.3 | E43: =IF(ISNUMBER(D43),IF(ISNUMBER(W37),ABS(W37-D43),"N/A"),"N/A") | F43: =IF(ISNUMBER(D43),IF(AND(ISNUMBER(W37),ABS(W37-D43)<=0.0001),"PASS","FAIL"),IF(AND(NOT(ISNUMBER(W37)),W37=D43),"PASS","FAIL"))
B45: 5. VAT-exclusive display, both fee types (TC5)
B46: Metric | C46: Excel Result | D46: Python Reference | E46: Difference | F46: PASS / FAIL
...

Sheet 06_MODE_C_SIMULATOR
B2: 06. MODE C Simulator — Allowable Direct Cost (Interactive)
B4: INPUT (노란 셀만 입력, 단일 컴포넌트 기준)
B5: Target Market Price | C5: 110000 | D5: product.price_components[].target_market_price — effective(할인 반영 후) 거래가격
B6: Price Includes VAT | C6: TRUE | D6: TRUE=시장가에 VAT 포함 / FALSE=별도 / 빈칸=모름
B7: VAT Rate (v) | C7: 0.1 | D7: a=0이면 ADC 계산에 불필요. N/G는 각자의 조건에서만 필요 (SPEC.md §6)
B8: Target Contribution Margin Rate (t) | C8: 0.3 | D8: 0 이상 1 미만이어야 함 (>=1 또는 <0은 ERROR)
B9: Fixed-Amount Variable Cost (F) | C9: 1000 | D9: variable_selling_delivery 중 금액형 항목 합계 (product_service_direct_cost 제외)
B10: Net-Sales Fee Rate (b) | C10: 0.1 | D10: rate_of_net_sales 합계 — N에 곱함. 없으면 0
B11: Gross-Payment Fee Rate (a) | C11: 0.03 | D11: rate_of_gross_payment 합계 — G에 곱함. 없으면 0
B12: Actual Direct Cost | C12: 50000 | D12: 실제 product_service_direct_cost 합계 — ADC 계산에 절대 사용되지 않음(dependency isolation)
B13: Variable Cost Allocation Status (Excel simulation control — not a schema field) | C13: none | D13: Excel-only. F/b/a(변동비)의 공유비용 배부 상태 시뮬레이션. none=정상 계산 / unresolved=배부 미구현(ADC/gap/CM/CMR까지 전부 UNKNOWN) / invalid=shared+direct 모순(전부 ERROR).
B14: Direct Cost Allocation Status (Excel simulation control — not a schema field) | C14: none | D14: Excel-only. actual_direct_cost만의 공유비용 배부 상태 시뮬레이션 — F/b/a와 완전히 분리된 컨트롤. none=정상 / unresolved=배부 미구현(actual_direct_cost·gap만 UNKNOWN) / invalid=모순(둘 다 ERROR). ADC·expected_contribution_margin(_rate)은 이 값과 무관하게 절대 변하지 않아야 함(가장 중요한 dependency-isolation 테스트, SPEC.md §9).
B16: RESULT (계산값 — 직접 입력 금지)
B17: Market Net Sales ex VAT (N) | C17: =IFERROR(IF(ISBLANK($C$5),"UNKNOWN",IF(ISBLANK($C$6),"UNKNOWN",IF($C$6=FALSE,$C$5,IF(ISBLANK($C$7),"UNKNOWN",$C$5/(1+$C$7))))),"ERROR") | D17: N — price_includes_vat=FALSE→시장가 그대로 / TRUE→÷(1+v)
B18: Market Gross Payment incl VAT (G) | C18: =IFERROR(IF(ISBLANK($C$5),"UNKNOWN",IF(ISBLANK($C$6),"UNKNOWN",IF($C$6=TRUE,$C$5,IF(ISBLANK($C$7),"UNKNOWN",$C$5*(1+$C$7))))),"ERROR") | D18: G — price_includes_vat=TRUE→시장가 그대로 / FALSE→×(1+v)
B19: Allowable Direct Cost (ADC) | C19: =IFERROR(IF(OR(C17="ERROR",J24="ERROR",K24="ERROR",L24="ERROR",M24="ERROR"),"ERROR",IF(OR(NOT(ISNUMBER(C17)),NOT(ISNUMBER(J24)),NOT(ISNUMBER(K24)),NOT(ISNUMBER(L24)),NOT(ISNUMBER(M24))),"UNKNOWN",IF(M24>0,IF(C18="ERROR","ERROR",IF(NOT(ISNUMBER(C18)),"UNKNOWN",C17*(1-J24-L24)-M24*C18-K24)),C17*(1-J24-L24)-K24))),"ERROR") | D19: ADC = N×(1−t−b) − a×G − F (a=0이면 G 참조 안 함)
B20: Actual Direct Cost | C20: =IFERROR(IF($C$14="invalid","ERROR",IF($C$14="unresolved","UNKNOWN",IF(ISBLANK($C$12),"UNKNOWN",$C$12))),"ERROR") | D20: 실제 직접원가 — ADC와 완전히 독립 (Direct Cost Allocation Status만 영향)
B21: Direct Cost Gap (ADC − Actual) | C21: =IFERROR(IF(OR(C19="ERROR",C20="ERROR"),"ERROR",IF(OR(NOT(ISNUMBER(C19)),NOT(ISNUMBER(C20))),"UNKNOWN",C19-C20)),"ERROR") | D21: = ADC − Actual Direct Cost. 양수=여유, 음수=초과
B22: Expected Contribution Margin | C22: =IFERROR(IF(C19="ERROR","ERROR",IF(NOT(ISNUMBER(C19)),"UNKNOWN",IF(M24>0,C17-C19-K24-L24*C17-M24*C18,C17-C19-K24-L24*C17))),"ERROR") | D22: = N − ADC − F − b×N − a×G (역산식과 독립적인 비용구조 재계산)
B23: Expected CM Rate | C23: =IFERROR(IF(C22="ERROR","ERROR",IF(NOT(ISNUMBER(C22)),"UNKNOWN",IF(C17=0,"ERROR",C22/C17))),"ERROR") | D23: = CM / N. N=0이면 ERROR(미입력이 아니라 계산불가)
J24: =IFERROR(IF(ISBLANK($C$8),"UNKNOWN",IF(OR($C$8<0,$C$8>=1),"ERROR",$C$8)),"ERROR") | K24: =IFERROR(IF($C$13="invalid","ERROR",IF($C$13="unresolved","UNKNOWN",IF(ISBLANK($C$9),"UNKNOWN",$C$9))),"ERROR") | L24: =IFERROR(IF($C$13="invalid","ERROR",IF($C$13="unresolved","UNKNOWN",IF(ISBLANK($C$10),"UNKNOWN",$C$10))),"ERROR") | M24: =IFERROR(IF($C$13="invalid","ERROR",IF($C$13="unresolved","UNKNOWN",IF(ISBLANK($C$11),"UNKNOWN",$C$11))),"ERROR")
B26: Negative ADC? | C26: =IF(ISNUMBER(C19),IF(C19<0,"YES — NEGATIVE_ALLOWABLE_COST (경고, ERROR 아님)","NO"),"N/A")
B27: Self-Check: |CMR − t| ≤ 0.0001? | C27: =IF(NOT(ISNUMBER(C23)),"N/A",IF(ABS(C23-$C$8)<=0.0001,"PASS","FAIL")) | D27: expected_contribution_margin은 t×N이 아니라 비용구조(N-ADC-F-bN-aG)로 독립 재계산됩니다. 그 결과로 얻은 CMR(=CM/N)이 목표 t와 tolerance 내에서 일치하는지 진단하는 별도 셀. MODE C의 공식 출력 metric은 아님 — 산술 오류를 잡기 위한 진단용.
B28: STATUS
B29: Overall Status | C29: =IF((IF(C17="ERROR",1,0)+IF(C18="ERROR",1,0)+IF(C19="ERROR",1,0)+IF(C20="ERROR",1,0)+IF(C21="ERROR",1,0)+IF(C22="ERROR",1,0)+IF(C23="ERROR",1,0))>0,"ERROR — 목표 불가능 또는 입력값 모순",IF((IF(C17="UNKNOWN",1,0)+IF(C18="UNKNOWN",1,0)+IF(C19="UNKNOWN",1,0)+IF(C20="UNKNOWN",1,0)+IF(C21="UNKNOWN",1,0)+IF(C22="UNKNOWN",1,0)+IF(C23="UNKNOWN",1,0))>0,"INCOMPLETE — 일부 지표 UNKNOWN","OK — 전체 계산 완료"))
B30: blank = UNKNOWN / 0 = explicit zero
B32: DASHBOARD CARD
B33: Market Net Sales (N) | E33: Allowable Direct Cost | H33: Actual Direct Cost
B34: =C17 | E34: =C19 | H34: =C20
B36: Direct Cost Gap | E36: Expected CM | H36: Expected CM Rate
B37: =C21 | E37: =C22 | H37: =C23

Sheet 07_MODE_C_PARITY_TEST
B2: 07. Python Engine vs Excel Formula — MODE C Parity Test
B3: 각 케이스는 docs/features/mode_c_allowable_cost/CASE.md의 TC1-20에 대응하며, Excel에 동일 입력값을 리터럴로 심어 06_MODE_C_SIMULATOR와 같은 수식(build_mode_c_formulas)으로 독립 재계산하고, Python 참조값(core/engine/modes/mode_c.py 실행 결과, 빌드 시점에 고정)과 비교합니다. 허용오차 0.01(금액) / 0.0001(비율). TC14/TC15/TC18은 Variable Cost Allocation Status로, TC20은 Direct Cost Allocation Status로 공유비용 배부 미구현/모순 상태를 시뮬레이션합니다 — TC19/TC20은 특히 Direct Cost Allocation Status를 바꿔도 allowable_direct_cost/expected_contribution_margin(_rate)이 전혀 영향받지 않는지를 실시간으로 검증하는, 가장 중요한 dependency-isolation 케이스입니다. 20개 전부 live Excel evaluation.
B5: TC1. Simple, no fee at all
B6: Metric | C6: Excel Result | D6: Python Reference | E6: Difference | F6: PASS / FAIL
B7: Market Net Sales ex VAT (N) | C7: =S7 | D7: 100000 | E7: =IF(ISNUMBER(D7),IF(ISNUMBER(S7),ABS(S7-D7),"N/A"),"N/A") | F7: =IFERROR(IF(ISNUMBER(D7),IF(ISNUMBER(S7),IF(ABS(S7-D7)<=0.01,"PASS","FAIL"),"FAIL"),IF(NOT(ISNUMBER(S7)),IF(S7=D7,"PASS","FAIL"),"FAIL")),"FAIL") | I7: 100000 | J7: FALSE | L7: 0.3 | M7: 0 | N7: 0 | O7: 0 | P7: 0 | Q7: none | R7: none | S7: =IFERROR(IF(ISBLANK($I$7),"UNKNOWN",IF(ISBLANK($J$7),"UNKNOWN",IF($J$7=FALSE,$I$7,IF(ISBLANK($K$7),"UNKNOWN",$I$7/(1+$K$7))))),"ERROR") | T7: =IFERROR(IF(ISBLANK($I$7),"UNKNOWN",IF(ISBLANK($J$7),"UNKNOWN",IF($J$7=TRUE,$I$7,IF(ISBLANK($K$7),"UNKNOWN",$I$7*(1+$K$7))))),"ERROR") | U7: =IFERROR(IF(OR(S7="ERROR",Z7="ERROR",AA7="ERROR",AB7="ERROR",AC7="ERROR"),"ERROR",IF(OR(NOT(ISNUMBER(S7)),NOT(ISNUMBER(Z7)),NOT(ISNUMBER(AA7)),NOT(ISNUMBER(AB7)),NOT(ISNUMBER(AC7))),"UNKNOWN",IF(AC7>0,IF(T7="ERROR","ERROR",IF(NOT(ISNUMBER(T7)),"UNKNOWN",S7*(1-Z7-AB7)-AC7*T7-AA7)),S7*(1-Z7-AB7)-AA7))),"ERROR") | V7: =IFERROR(IF($R$7="invalid","ERROR",IF($R$7="unresolved","UNKNOWN",IF(ISBLANK($P$7),"UNKNOWN",$P$7))),"ERROR") | W7: =IFERROR(IF(OR(U7="ERROR",V7="ERROR"),"ERROR",IF(OR(NOT(ISNUMBER(U7)),NOT(ISNUMBER(V7))),"UNKNOWN",U7-V7)),"ERROR") | X7: =IFERROR(IF(U7="ERROR","ERROR",IF(NOT(ISNUMBER(U7)),"UNKNOWN",IF(AC7>0,S7-U7-AA7-AB7*S7-AC7*T7,S7-U7-AA7-AB7*S7))),"ERROR") | Y7: =IFERROR(IF(X7="ERROR","ERROR",IF(NOT(ISNUMBER(X7)),"UNKNOWN",IF(S7=0,"ERROR",X7/S7))),"ERROR") | Z7: =IFERROR(IF(ISBLANK($L$7),"UNKNOWN",IF(OR($L$7<0,$L$7>=1),"ERROR",$L$7)),"ERROR") | AA7: =IFERROR(IF($Q$7="invalid","ERROR",IF($Q$7="unresolved","UNKNOWN",IF(ISBLANK($M$7),"UNKNOWN",$M$7))),"ERROR") | AB7: =IFERROR(IF($Q$7="invalid","ERROR",IF($Q$7="unresolved","UNKNOWN",IF(ISBLANK($N$7),"UNKNOWN",$N$7))),"ERROR") | AC7: =IFERROR(IF($Q$7="invalid","ERROR",IF($Q$7="unresolved","UNKNOWN",IF(ISBLANK($O$7),"UNKNOWN",$O$7))),"ERROR")
B8: Market Gross Payment incl VAT (G) | C8: =T7 | D8: UNKNOWN | E8: =IF(ISNUMBER(D8),IF(ISNUMBER(T7),ABS(T7-D8),"N/A"),"N/A") | F8: =IFERROR(IF(ISNUMBER(D8),IF(ISNUMBER(T7),IF(ABS(T7-D8)<=0.01,"PASS","FAIL"),"FAIL"),IF(NOT(ISNUMBER(T7)),IF(T7=D8,"PASS","FAIL"),"FAIL")),"FAIL")
B9: Allowable Direct Cost (ADC) | C9: =U7 | D9: 70000 | E9: =IF(ISNUMBER(D9),IF(ISNUMBER(U7),ABS(U7-D9),"N/A"),"N/A") | F9: =IFERROR(IF(ISNUMBER(D9),IF(ISNUMBER(U7),IF(ABS(U7-D9)<=0.01,"PASS","FAIL"),"FAIL"),IF(NOT(ISNUMBER(U7)),IF(U7=D9,"PASS","FAIL"),"FAIL")),"FAIL")
B10: Actual Direct Cost | C10: =V7 | D10: 0 | E10: =IF(ISNUMBER(D10),IF(ISNUMBER(V7),ABS(V7-D10),"N/A"),"N/A") | F10: =IFERROR(IF(ISNUMBER(D10),IF(ISNUMBER(V7),IF(ABS(V7-D10)<=0.01,"PASS","FAIL"),"FAIL"),IF(NOT(ISNUMBER(V7)),IF(V7=D10,"PASS","FAIL"),"FAIL")),"FAIL")
B11: Direct Cost Gap (ADC − Actual) | C11: =W7 | D11: 70000 | E11: =IF(ISNUMBER(D11),IF(ISNUMBER(W7),ABS(W7-D11),"N/A"),"N/A") | F11: =IFERROR(IF(ISNUMBER(D11),IF(ISNUMBER(W7),IF(ABS(W7-D11)<=0.01,"PASS","FAIL"),"FAIL"),IF(NOT(ISNUMBER(W7)),IF(W7=D11,"PASS","FAIL"),"FAIL")),"FAIL")
B12: Expected Contribution Margin | C12: =X7 | D12: 30000 | E12: =IF(ISNUMBER(D12),IF(ISNUMBER(X7),ABS(X7-D12),"N/A"),"N/A") | F12: =IFERROR(IF(ISNUMBER(D12),IF(ISNUMBER(X7),IF(ABS(X7-D12)<=0.01,"PASS","FAIL"),"FAIL"),IF(NOT(ISNUMBER(X7)),IF(X7=D12,"PASS","FAIL"),"FAIL")),"FAIL")
B13: Expected CM Rate | C13: =Y7 | D13: 0.3 | E13: =IF(ISNUMBER(D13),IF(ISNUMBER(Y7),ABS(Y7-D13),"N/A"),"N/A") | F13: =IFERROR(IF(ISNUMBER(D13),IF(ISNUMBER(Y7),IF(ABS(Y7-D13)<=0.0001,"PASS","FAIL"),"FAIL"),IF(NOT(ISNUMBER(Y7)),IF(Y7=D13,"PASS","FAIL"),"FAIL")),"FAIL")
B15: TC2. Fixed-amount variable cost (F>0)
B16: Metric | C16: Excel Result | D16: Python Reference | E16: Difference | F16: PASS / FAIL
B17: Market Net Sales ex VAT (N) | C17: =S17 | D17: 100000 | E17: =IF(ISNUMBER(D17),IF(ISNUMBER(S17),ABS(S17-D17),"N/A"),"N/A") | F17: =IFERROR(IF(ISNUMBER(D17),IF(ISNUMBER(S17),IF(ABS(S17-D17)<=0.01,"PASS","FAIL"),"FAIL"),IF(NOT(ISNUMBER(S17)),IF(S17=D17,"PASS","FAIL"),"FAIL")),"FAIL") | I17: 100000 | J17: FALSE | L17: 0.3 | M17: 5000 | N17: 0 | O17: 0 | P17: 0 | Q17: none | R17: none | S17: =IFERROR(IF(ISBLANK($I$17),"UNKNOWN",IF(ISBLANK($J$17),"UNKNOWN",IF($J$17=FALSE,$I$17,IF(ISBLANK($K$17),"UNKNOWN",$I$17/(1+$K$17))))),"ERROR") | T17: =IFERROR(IF(ISBLANK($I$17),"UNKNOWN",IF(ISBLANK($J$17),"UNKNOWN",IF($J$17=TRUE,$I$17,IF(ISBLANK($K$17),"UNKNOWN",$I$17*(1+$K$17))))),"ERROR") | U17: =IFERROR(IF(OR(S17="ERROR",Z17="ERROR",AA17="ERROR",AB17="ERROR",AC17="ERROR"),"ERROR",IF(OR(NOT(ISNUMBER(S17)),NOT(ISNUMBER(Z17)),NOT(ISNUMBER(AA17)),NOT(ISNUMBER(AB17)),NOT(ISNUMBER(AC17))),"UNKNOWN",IF(AC17>0,IF(T17="ERROR","ERROR",IF(NOT(ISNUMBER(T17)),"UNKNOWN",S17*(1-Z17-AB17)-AC17*T17-AA17)),S17*(1-Z17-AB17)-AA17))),"ERROR") | V17: =IFERROR(IF($R$17="invalid","ERROR",IF($R$17="unresolved","UNKNOWN",IF(ISBLANK($P$17),"UNKNOWN",$P$17))),"ERROR") | W17: =IFERROR(IF(OR(U17="ERROR",V17="ERROR"),"ERROR",IF(OR(NOT(ISNUMBER(U17)),NOT(ISNUMBER(V17))),"UNKNOWN",U17-V17)),"ERROR") | X17: =IFERROR(IF(U17="ERROR","ERROR",IF(NOT(ISNUMBER(U17)),"UNKNOWN",IF(AC17>0,S17-U17-AA17-AB17*S17-AC17*T17,S17-U17-AA17-AB17*S17))),"ERROR") | Y17: =IFERROR(IF(X17="ERROR","ERROR",IF(NOT(ISNUMBER(X17)),"UNKNOWN",IF(S17=0,"ERROR",X17/S17))),"ERROR") | Z17: =IFERROR(IF(ISBLANK($L$17),"UNKNOWN",IF(OR($L$17<0,$L$17>=1),"ERROR",$L$17)),"ERROR") | AA17: =IFERROR(IF($Q$17="invalid","ERROR",IF($Q$17="unresolved","UNKNOWN",IF(ISBLANK($M$17),"UNKNOWN",$M$17))),"ERROR") | AB17: =IFERROR(IF($Q$17="invalid","ERROR",IF($Q$17="unresolved","UNKNOWN",IF(ISBLANK($N$17),"UNKNOWN",$N$17))),"ERROR") | AC17: =IFERROR(IF($Q$17="invalid","ERROR",IF($Q$17="unresolved","UNKNOWN",IF(ISBLANK($O$17),"UNKNOWN",$O$17))),"ERROR")
B18: Market Gross Payment incl VAT (G) | C18: =T17 | D18: UNKNOWN | E18: =IF(ISNUMBER(D18),IF(ISNUMBER(T17),ABS(T17-D18),"N/A"),"N/A") | F18: =IFERROR(IF(ISNUMBER(D18),IF(ISNUMBER(T17),IF(ABS(T17-D18)<=0.01,"PASS","FAIL"),"FAIL"),IF(NOT(ISNUMBER(T17)),IF(T17=D18,"PASS","FAIL"),"FAIL")),"FAIL")
B19: Allowable Direct Cost (ADC) | C19: =U17 | D19: 65000 | E19: =IF(ISNUMBER(D19),IF(ISNUMBER(U17),ABS(U17-D19),"N/A"),"N/A") | F19: =IFERROR(IF(ISNUMBER(D19),IF(ISNUMBER(U17),IF(ABS(U17-D19)<=0.01,"PASS","FAIL"),"FAIL"),IF(NOT(ISNUMBER(U17)),IF(U17=D19,"PASS","FAIL"),"FAIL")),"FAIL")
B20: Actual Direct Cost | C20: =V17 | D20: 0 | E20: =IF(ISNUMBER(D20),IF(ISNUMBER(V17),ABS(V17-D20),"N/A"),"N/A") | F20: =IFERROR(IF(ISNUMBER(D20),IF(ISNUMBER(V17),IF(ABS(V17-D20)<=0.01,"PASS","FAIL"),"FAIL"),IF(NOT(ISNUMBER(V17)),IF(V17=D20,"PASS","FAIL"),"FAIL")),"FAIL")
B21: Direct Cost Gap (ADC − Actual) | C21: =W17 | D21: 65000 | E21: =IF(ISNUMBER(D21),IF(ISNUMBER(W17),ABS(W17-D21),"N/A"),"N/A") | F21: =IFERROR(IF(ISNUMBER(D21),IF(ISNUMBER(W17),IF(ABS(W17-D21)<=0.01,"PASS","FAIL"),"FAIL"),IF(NOT(ISNUMBER(W17)),IF(W17=D21,"PASS","FAIL"),"FAIL")),"FAIL")
B22: Expected Contribution Margin | C22: =X17 | D22: 30000 | E22: =IF(ISNUMBER(D22),IF(ISNUMBER(X17),ABS(X17-D22),"N/A"),"N/A") | F22: =IFERROR(IF(ISNUMBER(D22),IF(ISNUMBER(X17),IF(ABS(X17-D22)<=0.01,"PASS","FAIL"),"FAIL"),IF(NOT(ISNUMBER(X17)),IF(X17=D22,"PASS","FAIL"),"FAIL")),"FAIL")
B23: Expected CM Rate | C23: =Y17 | D23: 0.3 | E23: =IF(ISNUMBER(D23),IF(ISNUMBER(Y17),ABS(Y17-D23),"N/A"),"N/A") | F23: =IFERROR(IF(ISNUMBER(D23),IF(ISNUMBER(Y17),IF(ABS(Y17-D23)<=0.0001,"PASS","FAIL"),"FAIL"),IF(NOT(ISNUMBER(Y17)),IF(Y17=D23,"PASS","FAIL"),"FAIL")),"FAIL")
B25: TC3. Net-sales fee only (b>0)
B26: Metric | C26: Excel Result | D26: Python Reference | E26: Difference | F26: PASS / FAIL
B27: Market Net Sales ex VAT (N) | C27: =S27 | D27: 100000 | E27: =IF(ISNUMBER(D27),IF(ISNUMBER(S27),ABS(S27-D27),"N/A"),"N/A") | F27: =IFERROR(IF(ISNUMBER(D27),IF(ISNUMBER(S27),IF(ABS(S27-D27)<=0.01,"PASS","FAIL"),"FAIL"),IF(NOT(ISNUMBER(S27)),IF(S27=D27,"PASS","FAIL"),"FAIL")),"FAIL") | I27: 100000 | J27: FALSE | L27: 0.3 | M27: 0 | N27: 0.1 | O27: 0 | P27: 0 | Q27: none | R27: none | S27: =IFERROR(IF(ISBLANK($I$27),"UNKNOWN",IF(ISBLANK($J$27),"UNKNOWN",IF($J$27=FALSE,$I$27,IF(ISBLANK($K$27),"UNKNOWN",$I$27/(1+$K$27))))),"ERROR") | T27: =IFERROR(IF(ISBLANK($I$27),"UNKNOWN",IF(ISBLANK($J$27),"UNKNOWN",IF($J$27=TRUE,$I$27,IF(ISBLANK($K$27),"UNKNOWN",$I$27*(1+$K$27))))),"ERROR") | U27: =IFERROR(IF(OR(S27="ERROR",Z27="ERROR",AA27="ERROR",AB27="ERROR",AC27="ERROR"),"ERROR",IF(OR(NOT(ISNUMBER(S27)),NOT(ISNUMBER(Z27)),NOT(ISNUMBER(AA27)),NOT(ISNUMBER(AB27)),NOT(ISNUMBER(AC27))),"UNKNOWN",IF(AC27>0,IF(T27="ERROR","ERROR",IF(NOT(ISNUMBER(T27)),"UNKNOWN",S27*(1-Z27-AB27)-AC27*T27-AA27)),S27*(1-Z27-AB27)-AA27))),"ERROR") | V27: =IFERROR(IF($R$27="invalid","ERROR",IF($R$27="unresolved","UNKNOWN",IF(ISBLANK($P$27),"UNKNOWN",$P$27))),"ERROR") | W27: =IFERROR(IF(OR(U27="ERROR",V27="ERROR"),"ERROR",IF(OR(NOT(ISNUMBER(U27)),NOT(ISNUMBER(V27))),"UNKNOWN",U27-V27)),"ERROR") | X27: =IFERROR(IF(U27="ERROR","ERROR",IF(NOT(ISNUMBER(U27)),"UNKNOWN",IF(AC27>0,S27-U27-AA27-AB27*S27-AC27*T27,S27-U27-AA27-AB27*S27))),"ERROR") | Y27: =IFERROR(IF(X27="ERROR","ERROR",IF(NOT(ISNUMBER(X27)),"UNKNOWN",IF(S27=0,"ERROR",X27/S27))),"ERROR") | Z27: =IFERROR(IF(ISBLANK($L$27),"UNKNOWN",IF(OR($L$27<0,$L$27>=1),"ERROR",$L$27)),"ERROR") | AA27: =IFERROR(IF($Q$27="invalid","ERROR",IF($Q$27="unresolved","UNKNOWN",IF(ISBLANK($M$27),"UNKNOWN",$M$27))),"ERROR") | AB27: =IFERROR(IF($Q$27="invalid","ERROR",IF($Q$27="unresolved","UNKNOWN",IF(ISBLANK($N$27),"UNKNOWN",$N$27))),"ERROR") | AC27: =IFERROR(IF($Q$27="invalid","ERROR",IF($Q$27="unresolved","UNKNOWN",IF(ISBLANK($O$27),"UNKNOWN",$O$27))),"ERROR")
B28: Market Gross Payment incl VAT (G) | C28: =T27 | D28: UNKNOWN | E28: =IF(ISNUMBER(D28),IF(ISNUMBER(T27),ABS(T27-D28),"N/A"),"N/A") | F28: =IFERROR(IF(ISNUMBER(D28),IF(ISNUMBER(T27),IF(ABS(T27-D28)<=0.01,"PASS","FAIL"),"FAIL"),IF(NOT(ISNUMBER(T27)),IF(T27=D28,"PASS","FAIL"),"FAIL")),"FAIL")
B29: Allowable Direct Cost (ADC) | C29: =U27 | D29: 60000 | E29: =IF(ISNUMBER(D29),IF(ISNUMBER(U27),ABS(U27-D29),"N/A"),"N/A") | F29: =IFERROR(IF(ISNUMBER(D29),IF(ISNUMBER(U27),IF(ABS(U27-D29)<=0.01,"PASS","FAIL"),"FAIL"),IF(NOT(ISNUMBER(U27)),IF(U27=D29,"PASS","FAIL"),"FAIL")),"FAIL")
B30: Actual Direct Cost | C30: =V27 | D30: 0 | E30: =IF(ISNUMBER(D30),IF(ISNUMBER(V27),ABS(V27-D30),"N/A"),"N/A") | F30: =IFERROR(IF(ISNUMBER(D30),IF(ISNUMBER(V27),IF(ABS(V27-D30)<=0.01,"PASS","FAIL"),"FAIL"),IF(NOT(ISNUMBER(V27)),IF(V27=D30,"PASS","FAIL"),"FAIL")),"FAIL")
B31: Direct Cost Gap (ADC − Actual) | C31: =W27 | D31: 60000 | E31: =IF(ISNUMBER(D31),IF(ISNUMBER(W27),ABS(W27-D31),"N/A"),"N/A") | F31: =IFERROR(IF(ISNUMBER(D31),IF(ISNUMBER(W27),IF(ABS(W27-D31)<=0.01,"PASS","FAIL"),"FAIL"),IF(NOT(ISNUMBER(W27)),IF(W27=D31,"PASS","FAIL"),"FAIL")),"FAIL")
B32: Expected Contribution Margin | C32: =X27 | D32: 30000 | E32: =IF(ISNUMBER(D32),IF(ISNUMBER(X27),ABS(X27-D32),"N/A"),"N/A") | F32: =IFERROR(IF(ISNUMBER(D32),IF(ISNUMBER(X27),IF(ABS(X27-D32)<=0.01,"PASS","FAIL"),"FAIL"),IF(NOT(ISNUMBER(X27)),IF(X27=D32,"PASS","FAIL"),"FAIL")),"FAIL")
B33: Expected CM Rate | C33: =Y27 | D33: 0.3 | E33: =IF(ISNUMBER(D33),IF(ISNUMBER(Y27),ABS(Y27-D33),"N/A"),"N/A") | F33: =IFERROR(IF(ISNUMBER(D33),IF(ISNUMBER(Y27),IF(ABS(Y27-D33)<=0.0001,"PASS","FAIL"),"FAIL"),IF(NOT(ISNUMBER(Y27)),IF(Y27=D33,"PASS","FAIL"),"FAIL")),"FAIL")
B35: TC4. Gross-payment fee, VAT-exclusive display, v known
B36: Metric | C36: Excel Result | D36: Python Reference | E36: Difference | F36: PASS / FAIL
B37: Market Net Sales ex VAT (N) | C37: =S37 | D37: 100000 | E37: =IF(ISNUMBER(D37),IF(ISNUMBER(S37),ABS(S37-D37),"N/A"),"N/A") | F37: =IFERROR(IF(ISNUMBER(D37),IF(ISNUMBER(S37),IF(ABS(S37-D37)<=0.01,"PASS","FAIL"),"FAIL"),IF(NOT(ISNUMBER(S37)),IF(S37=D37,"PASS","FAIL"),"FAIL")),"FAIL") | I37: 100000 | J37: FALSE | K37: 0.1 | L37: 0.3 | M37: 0 | N37: 0 | O37: 0.05 | P37: 0 | Q37: none | R37: none | S37: =IFERROR(IF(ISBLANK($I$37),"UNKNOWN",IF(ISBLANK($J$37),"UNKNOWN",IF($J$37=FALSE,$I$37,IF(ISBLANK($K$37),"UNKNOWN",$I$37/(1+$K$37))))),"ERROR") | T37: =IFERROR(IF(ISBLANK($I$37),"UNKNOWN",IF(ISBLANK($J$37),"UNKNOWN",IF($J$37=TRUE,$I$37,IF(ISBLANK($K$37),"UNKNOWN",$I$37*(1+$K$37))))),"ERROR") | U37: =IFERROR(IF(OR(S37="ERROR",Z37="ERROR",AA37="ERROR",AB37="ERROR",AC37="ERROR"),"ERROR",IF(OR(NOT(ISNUMBER(S37)),NOT(ISNUMBER(Z37)),NOT(ISNUMBER(AA37)),NOT(ISNUMBER(AB37)),NOT(ISNUMBER(AC37))),"UNKNOWN",IF(AC37>0,IF(T37="ERROR","ERROR",IF(NOT(ISNUMBER(T37)),"UNKNOWN",S37*(1-Z37-AB37)-AC37*T37-AA37)),S37*(1-Z37-AB37)-AA37))),"ERROR") | V37: =IFERROR(IF($R$37="invalid","ERROR",IF($R$37="unresolved","UNKNOWN",IF(ISBLANK($P$37),"UNKNOWN",$P$37))),"ERROR") | W37: =IFERROR(IF(OR(U37="ERROR",V37="ERROR"),"ERROR",IF(OR(NOT(ISNUMBER(U37)),NOT(ISNUMBER(V37))),"UNKNOWN",U37-V37)),"ERROR") | X37: =IFERROR(IF(U37="ERROR","ERROR",IF(NOT(ISNUMBER(U37)),"UNKNOWN",IF(AC37>0,S37-U37-AA37-AB37*S37-AC37*T37,S37-U37-AA37-AB37*S37))),"ERROR") | Y37: =IFERROR(IF(X37="ERROR","ERROR",IF(NOT(ISNUMBER(X37)),"UNKNOWN",IF(S37=0,"ERROR",X37/S37))),"ERROR") | Z37: =IFERROR(IF(ISBLANK($L$37),"UNKNOWN",IF(OR($L$37<0,$L$37>=1),"ERROR",$L$37)),"ERROR") | AA37: =IFERROR(IF($Q$37="invalid","ERROR",IF($Q$37="unresolved","UNKNOWN",IF(ISBLANK($M$37),"UNKNOWN",$M$37))),"ERROR") | AB37: =IFERROR(IF($Q$37="invalid","ERROR",IF($Q$37="unresolved","UNKNOWN",IF(ISBLANK($N$37),"UNKNOWN",$N$37))),"ERROR") | AC37: =IFERROR(IF($Q$37="invalid","ERROR",IF($Q$37="unresolved","UNKNOWN",IF(ISBLANK($O$37),"UNKNOWN",$O$37))),"ERROR")
B38: Market Gross Payment incl VAT (G) | C38: =T37 | D38: 110000 | E38: =IF(ISNUMBER(D38),IF(ISNUMBER(T37),ABS(T37-D38),"N/A"),"N/A") | F38: =IFERROR(IF(ISNUMBER(D38),IF(ISNUMBER(T37),IF(ABS(T37-D38)<=0.01,"PASS","FAIL"),"FAIL"),IF(NOT(ISNUMBER(T37)),IF(T37=D38,"PASS","FAIL"),"FAIL")),"FAIL")
B39: Allowable Direct Cost (ADC) | C39: =U37 | D39: 64500 | E39: =IF(ISNUMBER(D39),IF(ISNUMBER(U37),ABS(U37-D39),"N/A"),"N/A") | F39: =IFERROR(IF(ISNUMBER(D39),IF(ISNUMBER(U37),IF(ABS(U37-D39)<=0.01,"PASS","FAIL"),"FAIL"),IF(NOT(ISNUMBER(U37)),IF(U37=D39,"PASS","FAIL"),"FAIL")),"FAIL")
B40: Actual Direct Cost | C40: =V37 | D40: 0 | E40: =IF(ISNUMBER(D40),IF(ISNUMBER(V37),ABS(V37-D40),"N/A"),"N/A") | F40: =IFERROR(IF(ISNUMBER(D40),IF(ISNUMBER(V37),IF(ABS(V37-D40)<=0.01,"PASS","FAIL"),"FAIL"),IF(NOT(ISNUMBER(V37)),IF(V37=D40,"PASS","FAIL"),"FAIL")),"FAIL")
B41: Direct Cost Gap (ADC − Actual) | C41: =W37 | D41: 64500 | E41: =IF(ISNUMBER(D41),IF(ISNUMBER(W37),ABS(W37-D41),"N/A"),"N/A") | F41: =IFERROR(IF(ISNUMBER(D41),IF(ISNUMBER(W37),IF(ABS(W37-D41)<=0.01,"PASS","FAIL"),"FAIL"),IF(NOT(ISNUMBER(W37)),IF(W37=D41,"PASS","FAIL"),"FAIL")),"FAIL")
B42: Expected Contribution Margin | C42: =X37 | D42: 30000 | E42: =IF(ISNUMBER(D42),IF(ISNUMBER(X37),ABS(X37-D42),"N/A"),"N/A") | F42: =IFERROR(IF(ISNUMBER(D42),IF(ISNUMBER(X37),IF(ABS(X37-D42)<=0.01,"PASS","FAIL"),"FAIL"),IF(NOT(ISNUMBER(X37)),IF(X37=D42,"PASS","FAIL"),"FAIL")),"FAIL")
B43: Expected CM Rate | C43: =Y37 | D43: 0.3 | E43: =IF(ISNUMBER(D43),IF(ISNUMBER(Y37),ABS(Y37-D43),"N/A"),"N/A") | F43: =IFERROR(IF(ISNUMBER(D43),IF(ISNUMBER(Y37),IF(ABS(Y37-D43)<=0.0001,"PASS","FAIL"),"FAIL"),IF(NOT(ISNUMBER(Y37)),IF(Y37=D43,"PASS","FAIL"),"FAIL")),"FAIL")
B45: TC5. VAT-inclusive display, both fee types
B46: Metric | C46: Excel Result | D46: Python Reference | E46: Difference | F46: PASS / FAIL
...

Sheet 08_BEP_SIMULATOR
B2: 08. BEP Simulator — Break-Even Point (Interactive)
B4: INPUT (노란 셀만 입력, 단일 컴포넌트 기준)
B5: Actual Price | C5: 20000 | D5: 현재 실제 판매가격 — BEP는 항상 current price 기준 (MODE B/C 가격 대입 안 함)
B6: Price Includes VAT | C6: FALSE | D6: TRUE=판매가에 VAT 포함 / FALSE=별도 / 빈칸=모름
B7: VAT Rate (v) | C7: 0.1 | D7: a=0이면 CMu 계산에 불필요
B8: Product/Service Direct Cost | C8: 8000 | D8: CMu 계산에만 사용 (fixed_operating_cost와 무관)
